<?xml version="1.0" ?>
<robot name="rh56dfx">
  <!--
  ======================================================================
  INSPIRE HAND RH56DFX - PARAMETRIC MACRO
  ======================================================================
  -->
  <!-- ============================================================= -->
  <!-- MESH ROOT DIRECTORY                                           -->
  <!-- ============================================================= -->
  <!-- ============================================================= -->
  <!-- ROOT LINK (KINEMATIC ANCHOR)                                  -->
  <!-- ============================================================= -->
  <!-- ============================================================= -->
  <!--     WRIST BASE LINK                                           -->
  <!-- ============================================================= -->
  <link name="left_wrist_base_link">
    <!-- ================= INERTIAL ================= -->
    <inertial>
      <origin rpy="0 0 0" xyz="0.00191998775838077 -2.17534676938413E-08 0.0332314674517473" />
      <mass value="0.0695038666375085" />
      <inertia ixx="3.02480603452712E-05" ixy="-6.93925958512878E-11" ixz="5.01503749466725E-07" iyy="3.10214964795132E-05" iyz="-1.99074603834946E-11" izz="2.86515789056302E-05" />
    </inertial>
    <!-- ================= VISUAL ================= -->
    <visual>
      <origin rpy="0 0 0" xyz="0 0 0" />
      <geometry>
        <mesh filename="/workspace/external/rh56dfx_description/meshes/left/visual/left_wrist_base_link.STL" />
      </geometry>
      <material name="">
        <color rgba="1 1 1 1" />
      </material>
    </visual>
    <!-- ================= COLLISION ================= -->
    <collision>
      <origin rpy="0 0 0" xyz="0 0 0" />
      <geometry>
        <mesh filename="/workspace/external/rh56dfx_description/meshes/left/collision/left_wrist_base_link.STL" />
      </geometry>
      <material name="">
        <color rgba="1 0 0 1" />
      </material>
    </collision>
  </link>
  <!-- ========================================================= -->
  <!-- Wrist yaw joint                                          -->
  <!-- ========================================================= -->
  <link name="left_wrist_yaw">
    <!-- ================= INERTIAL ================= -->
    <inertial>
      <origin rpy="0 0 0" xyz="2.01072214434106E-11 0.00545897802039832 -0.0131919975376266" />
      <mass value="0.00277890553366271" />
      <inertia ixx="2.26417227467369E-07" ixy="8.61095341004759E-17" ixz="-2.38081373178298E-16" iyy="1.49079741679729E-07" iyz="-1.48845836759757E-08" izz="1.09370482342779E-07" />
    </inertial>
    <!-- ================= VISUAL ================= -->
    <visual>
      <origin rpy="0 0 0" xyz="0 0 0" />
      <geometry>
        <mesh filename="/workspace/external/rh56dfx_description/meshes/left/visual/left_wrist_yaw.STL" />
      </geometry>
      <material name="">
        <color rgba="1 1 1 1" />
      </material>
    </visual>
    <!-- ================= COLLISION ================= -->
    <collision>
      <origin rpy="0 0 0" xyz="0 0 0" />
      <geometry>
        <mesh filename="/workspace/external/rh56dfx_description/meshes/left/collision/left_wrist_yaw.STL" />
      </geometry>
      <material name="">
        <color rgba="1 0 0 1" />
      </material>
      <material name="">
        <color rgba="1 0 0 1" />
      </material>
    </collision>
  </link>
  <joint name="left_wrist_yaw_joint" type="revolute">
    <!-- ================= ORIGIN ================= -->
    <origin rpy="1.5708 0 -1.5708" xyz="-0.0055 0 0.0785" />
    <parent link="left_wrist_base_link" />
    <child link="left_wrist_yaw" />
    <axis xyz="0 0 -1" />
    <!-- ================= LIMITS ================= -->
    <limit effort="10" lower="-0.445" upper="0.445" velocity="2" />
  </joint>
  <!-- ========================================================= -->
  <!-- Hand base (palm carrier)                                  -->
  <!-- ========================================================= -->
  <link name="left_hand_base">
    <!-- ================= INERTIAL ================= -->
    <inertial>
      <origin rpy="0 0 0" xyz="-0.00203701184983107 0.0326112668966462 -0.0155668752323911" />
      <mass value="0.175357386592075" />
      <inertia ixx="0.000121544991663851" ixy="-6.56650332338833E-07" ixz="5.20578126071962E-07" iyy="7.52780099608673E-05" iyz="4.53525030951461E-07" izz="7.95760415441486E-05" />
    </inertial>
    <!-- ================= VISUAL ================= -->
    <visual>
      <origin rpy="0 0 0" xyz="0 0 0" />
      <geometry>
        <mesh filename="/workspace/external/rh56dfx_description/meshes/left/visual/left_hand_base.STL" />
      </geometry>
      <material name="">
        <color rgba="1 1 1 1" />
      </material>
    </visual>
    <!-- ================= COLLISION ================= -->
    <collision>
      <origin rpy="0 0 0" xyz="0 0 0" />
      <geometry>
        <mesh filename="/workspace/external/rh56dfx_description/meshes/left/collision/left_hand_base.STL" />
      </geometry>
      <material name="">
        <color rgba="1 0 0 1" />
      </material>
      <material name="">
        <color rgba="1 0 0 1" />
      </material>
    </collision>
  </link>
  <joint name="left_hand_base_joint" type="revolute">
    <!-- ================= ORIGIN ================= -->
    <origin rpy="-0.11587 1.5708 -0.11587" xyz="0.015 0 -0.0055" />
    <parent link="left_wrist_yaw" />
    <child link="left_hand_base" />
    <axis xyz="0 0 -1" />
    <!-- ================= LIMITS ================= -->
    <limit effort="10" lower="-0.3955" upper="0.386" velocity="2" />
  </joint>
  <!-- ========================================================= -->
  <!-- Fingers: thumb, index, middle, ring, little               -->
  <!-- ========================================================= -->
  <!--
    Mimic joints:
      - Used to reduce control dimensionality
      - Required for realistic finger curling
  -->
  <!-- THUMB -->
  <!-- right_thumb_1, right_thumb_2, ... -->
  <!-- index finger -->
  <!-- middle finger -->
  <!-- ring finger -->
  <!-- little finger -->
  <!-- ============================================================= -->
  <!-- THUMB 1                                                       -->
  <!-- ============================================================= -->
  <link name="left_thumb_1">
    <!-- ================= INERTIAL ================= -->
    <inertial>
      <origin rpy="0 0 0" xyz="0.000675346448543043 -0.00433551697891765 -0.00508780193489455" />
      <mass value="0.0048541771537782" />
      <inertia ixx="1.96094051160198E-07" ixy="3.4858314687744E-08" ixz="-3.39249138133518E-09" iyy="1.43278984955152E-07" iyz="8.1983806766273E-09" izz="1.68938152839344E-07" />
    </inertial>
    <!-- ================= VISUAL ================= -->
    <visual>
      <origin rpy="0 0 0" xyz="0 0 0" />
      <geometry>
        <mesh filename="/workspace/external/rh56dfx_description/meshes/left/visual/left_thumb_1.STL" />
      </geometry>
      <material name="">
        <color rgba="1 1 1 1" />
      </material>
    </visual>
    <!-- ================= COLLISION ================= -->
    <collision>
      <origin rpy="0 0 0" xyz="0 0 0" />
      <geometry>
        <mesh filename="/workspace/external/rh56dfx_description/meshes/left/collision/left_thumb_1.STL" />
      </geometry>
      <material name="">
        <color rgba="1 0 0 1" />
      </material>
      <material name="">
        <color rgba="1 0 0 1" />
      </material>
    </collision>
  </link>
  <joint name="left_thumb_1_joint" type="revolute">
    <!-- ================= ORIGIN ================= -->
    <origin rpy="-1.5707963267949 0 0" xyz="0.0150000040088096 0.0342999999998856 0.00640000024786605" />
    <parent link="left_hand_base" />
    <child link="left_thumb_1" />
    <axis xyz="0 0 1" />
    <!-- ================= LIMITS ================= -->
    <limit effort="10" lower="0" upper="1.310384" velocity="2" />
  </joint>
  <!-- ============================================================= -->
  <!-- THUMB 2.                                                      -->
  <!-- ============================================================= -->
  <link name="left_thumb_2">
    <!-- ================= INERTIAL ================= -->
    <inertial>
      <origin rpy="0 0 0" xyz="0.0217021678253 0.0140075970723664 0.00802372797249204" />
      <mass value="0.011197324578883" />
      <inertia ixx="1.69781612625836E-06" ixy="-7.99167330982163E-07" ixz="6.95615513975465E-10" iyy="1.86857468329596E-06" iyz="-2.37438335268391E-10" izz="3.3501396961086E-06" />
    </inertial>
    <!-- ================= VISUAL ================= -->
    <visual>
      <origin rpy="0 0 0" xyz="0 0 0" />
      <geometry>
        <mesh filename="/workspace/external/rh56dfx_description/meshes/left/visual/left_thumb_2.STL" />
      </geometry>
      <material name="">
        <color rgba="1 1 1 1" />
      </material>
    </visual>
    <!-- ================= COLLISION ================= -->
    <collision>
      <origin rpy="0 0 0" xyz="0 0 0" />
      <geometry>
        <mesh filename="/workspace/external/rh56dfx_description/meshes/left/collision/left_thumb_2.STL" />
      </geometry>
      <material name="">
        <color rgba="1 0 0 1" />
      </material>
    </collision>
  </link>
  <joint name="left_thumb_2_joint" type="revolute">
    <!-- ================= ORIGIN ================= -->
    <origin rpy="1.5707963267949 0 -1.30899693899575" xyz="0.0107038256289916 -0.00903759464150408 -0.00649999999999991" />
    <axis xyz="0 0 1" />
    <parent link="left_thumb_1" />
    <child link="left_thumb_2" />
    <limit effort="10" lower="0" upper="0.523477" velocity="2" />
  </joint>
  <!-- ============================================================= -->
  <!-- THUMB RUBBER 1                                                -->
  <!-- ============================================================= -->
  <link name="left_thumb_rubber_1">
    <inertial>
      <origin rpy="0 0 0" xyz="5.40162647625353E-05 0.00265236291170259 -0.00524128392726222" />
      <mass value="0.0014906283411173" />
      <inertia ixx="1.88752644928606E-07" ixy="-3.80267550036779E-11" ixz="-3.87652846240887E-10" iyy="8.68559982474995E-08" iyz="3.72404130676968E-09" izz="2.26622483357037E-07" />
    </inertial>
    <!-- ============================================================ -->
    <!-- ================= VISUAL ================= -->
    <visual>
      <origin rpy="0 0 0" xyz="0 0 0" />
      <geometry>
        <mesh filename="/workspace/external/rh56dfx_description/meshes/left/visual/left_thumb_rubber_1.STL" />
      </geometry>
      <material name="">
        <color rgba="0.298039215686275 0.298039215686275 0.298039215686275 1" />
      </material>
    </visual>
    <!-- ================= COLLISION ================= -->
  </link>
  <!-- ================= JOINT ================= -->
  <joint name="left_thumb_rubber_1_joint" type="fixed">
    <origin rpy="3.13815940276581 1.56040994467678 -0.950106044051694" xyz="0.013046553810162 0.0313855611442985 0.00799913310995912" />
    <parent link="left_thumb_2" />
    <child link="left_thumb_rubber_1" />
  </joint>
  <!-- ============================================================= -->
  <!-- THUMB 3                                                       -->
  <!-- ============================================================= -->
  <link name="left_thumb_3">
    <inertial>
      <origin rpy="0 0 0" xyz="0.009163924940713 -0.00021374698947753 0.00749980580117909" />
      <mass value="0.00226949921461618" />
      <inertia ixx="2.51533206255898E-07" ixy="-6.42880570532076E-08" ixz="-1.61781119018821E-12" iyy="1.99322726365665E-07" iyz="-2.2825448825002E-12" izz="2.99631274061669E-07" />
    </inertial>
    <!-- ============================================================ -->
    <!-- ================= VISUAL ================= -->
    <visual>
      <origin rpy="0 0 0" xyz="0 0 0" />
      <geometry>
        <mesh filename="/workspace/external/rh56dfx_description/meshes/left/visual/left_thumb_3.STL" />
      </geometry>
      <material name="">
        <color rgba="1 1 1 1" />
      </material>
    </visual>
    <!-- ================= COLLISION ================= -->
    <collision>
      <origin rpy="0 0 0" xyz="0 0 0" />
      <geometry>
        <mesh filename="/workspace/external/rh56dfx_description/meshes/left/collision/left_thumb_3.STL" />
      </geometry>
      <material name="">
        <color rgba="1 0 0 1" />
      </material>
    </collision>
  </link>
  <!-- ================= JOINT ================= -->
  <joint name="left_thumb_3_joint" type="revolute">
    <origin rpy="0 0 0" xyz="0.0415838804016113 0.0375080548719081 0.000500000000000139" />
    <axis xyz="0 0 1" />
    <parent link="left_thumb_2" />
    <child link="left_thumb_3" />
    <limit effort="10" lower="0" upper="0.606844" velocity="2" />
    <!-- Mimic remains identical for both sides -->
    <mimic joint="left_thumb_2_joint" multiplier="1.1425" offset="0" />
  </joint>
  <!-- ============================================================= -->
  <!-- THUMB RUBBER 2                                                -->
  <!-- ============================================================= -->
  <link name="left_thumb_rubber_2">
    <inertial>
      <origin rpy="0 0 0" xyz="0.000162364162411777 -0.00288606836963476 -0.00905408809199784" />
      <mass value="0.000712407867806307" />
      <inertia ixx="4.20918600490016E-08" ixy="1.57348854903248E-10" ixz="1.3517068967957E-10" iyy="5.19681055248487E-08" iyz="-8.47497937683654E-09" izz="3.43794639288121E-08" />
    </inertial>
    <!-- ================= VISUAL ================= -->
    <visual>
      <origin rpy="0 0 0" xyz="0 0 0" />
      <geometry>
        <mesh filename="/workspace/external/rh56dfx_description/meshes/left/visual/left_thumb_rubber_2.STL" />
      </geometry>
      <material name="">
        <color rgba="0.298039215686275 0.298039215686275 0.298039215686275 1" />
      </material>
    </visual>
    <!-- ================= COLLISION ================= -->
  </link>
  <!-- ================= JOINT ================= -->
  <joint name="left_thumb_rubber_2_joint" type="fixed">
    <origin rpy="3.1415926439814 1.5531258063565 -1.04754422345685" xyz="0.00507003292533287 0.0118736037354008 0.00749998784521017" />
    <parent link="left_thumb_3" />
    <child link="left_thumb_rubber_2" />
  </joint>
  <!-- ============================================================= -->
  <!-- THUMB 4                                                       -->
  <!-- ============================================================= -->
  <link name="left_thumb_4">
    <inertial>
      <origin rpy="0 0 0" xyz="0.00556381842605758 0.00321786565136162 0.00598762078210302" />
      <mass value="0.000889838221404847" />
      <inertia ixx="2.7865190017362E-08" ixy="-1.6746511102932E-08" ixz="-3.94753258813797E-11" iyy="2.7870091174862E-08" iyz="-9.78353772270228E-11" izz="4.65705162837953E-08" />
    </inertial>
    <!-- ================= VISUAL ================= -->
    <visual>
      <origin rpy="0 0 0" xyz="0 0 0" />
      <geometry>
        <mesh filename="/workspace/external/rh56dfx_description/meshes/left/visual/left_thumb_4.STL" />
      </geometry>
      <material name="">
        <color rgba="1 1 1 1" />
      </material>
    </visual>
    <!-- ================= COLLISION ================= -->
    <collision>
      <origin rpy="0 0 0" xyz="0 0 0" />
      <geometry>
        <mesh filename="/workspace/external/rh56dfx_description/meshes/left/collision/left_thumb_4.STL" />
      </geometry>
      <material name="">
        <color rgba="1 0 0 1" />
      </material>
    </collision>
  </link>
  <!-- ================= JOINT ================= -->
  <joint name="left_thumb_4_joint" type="revolute">
    <origin rpy="0 0 0" xyz="0.0183934390204584 0.0132218952161126 0.0015" />
    <axis xyz="0 0 1" />
    <parent link="left_thumb_3" />
    <child link="left_thumb_4" />
    <limit effort="10" lower="0" upper="0.430866" velocity="2" />
    <mimic joint="left_thumb_3_joint" multiplier="0.7508" offset="0" />
  </joint>
  <!-- ============================================================= -->
  <!-- THUMB RUBBER 3                                                -->
  <!-- ============================================================= -->
  <link name="left_thumb_rubber_3">
    <inertial>
      <origin rpy="0 0 0" xyz="0.000268126145379105 -0.00224962169943535 -0.00745388764640809" />
      <mass value="0.00232428792968957" />
      <inertia ixx="1.17389753346854E-07" ixy="-2.01766145271162E-10" ixz="-5.32341724071167E-12" iyy="6.66695035665084E-08" iyz="5.60795555686444E-09" izz="1.17533665402913E-07" />
    </inertial>
    <!-- ================= VISUAL ================= -->
    <visual>
      <origin rpy="0 0 0" xyz="0 0 0" />
      <geometry>
        <mesh filename="/workspace/external/rh56dfx_description/meshes/left/visual/left_thumb_rubber_3.STL" />
      </geometry>
      <material name="">
        <color rgba="0.298039215686275 0.298039215686275 0.298039215686275 1" />
      </material>
    </visual>
    <!-- ================= COLLISION ================= -->
  </link>
  <!-- ================= JOINT ================= -->
  <joint name="left_thumb_rubber_3_joint" type="fixed">
    <origin rpy="3.1415305070896 1.53480155127221 -0.558130435251912" xyz="0.00161799622019054 0.00970901340884194 0.00599999825111228" />
    <parent link="left_thumb_4" />
    <child link="left_thumb_rubber_3" />
  </joint>
  <!-- ============================================================= -->
  <!-- THUMB PAD                                                     -->
  <!-- ============================================================= -->
  <link name="left_thumb_pad">
    <inertial>
      <origin rpy="0 0 0" xyz="-3.37221102708618E-08 0.00163135155510158 -0.00128514999690038" />
      <mass value="4.94551999339821E-05" />
      <inertia ixx="1.38213576910352E-10" ixy="4.70832523460883E-16" ixz="1.49104319677674E-15" iyy="8.81925937138397E-11" iyz="-2.69646775933513E-12" izz="1.80759780259597E-10" />
    </inertial>
    <!-- ================= VISUAL ================= -->
    <visual>
      <origin rpy="0 0 0" xyz="0 0 0" />
      <geometry>
        <mesh filename="/workspace/external/rh56dfx_description/meshes/left/visual/left_thumb_pad.STL" />
      </geometry>
      <material name="">
        <color rgba="0.298039215686275 0.298039215686275 0.298039215686275 1" />
      </material>
    </visual>
    <!-- ================= COLLISION ================= -->
    <collision>
      <origin rpy="0 0 0" xyz="0 0 0" />
      <geometry>
        <mesh filename="/workspace/external/rh56dfx_description/meshes/left/collision/left_thumb_pad.STL" />
      </geometry>
      <material name="">
        <color rgba="1 0 0 1" />
      </material>
    </collision>
  </link>
  <!-- ================= JOINT ================= -->
  <joint name="left_thumb_pad_joint" type="fixed">
    <origin rpy="0.280050125889912 -0.0359912824278135 -1.43908628784779E-05" xyz="4.85806106777231E-05 -0.00783602820251542 -0.00134991116931751" />
    <parent link="left_thumb_rubber_3" />
    <child link="left_thumb_pad" />
  </joint>
  <!-- ============================================================= -->
  <!-- THUMB TIP                                                     -->
  <!-- ============================================================= -->
  <link name="left_thumb_tip">
    <inertial>
      <origin rpy="0 0 0" xyz="2.50035524579084E-05 -0.00144636222857047 -0.00180325426020556" />
      <mass value="6.08897929255959E-05" />
      <inertia ixx="1.79108473399612E-10" ixy="4.05362271422041E-13" ixz="-3.71282029267747E-13" iyy="1.33990932373892E-10" iyz="-2.89649540571285E-11" izz="2.06216102977108E-10" />
    </inertial>
    <!-- ================= VISUAL ================= -->
    <visual>
      <origin rpy="0 0 0" xyz="0 0 0" />
      <geometry>
        <mesh filename="/workspace/external/rh56dfx_description/meshes/left/visual/left_thumb_tip.STL" />
      </geometry>
      <material name="">
        <color rgba="0.298039215686275 0.298039215686275 0.298039215686275 1" />
      </material>
    </visual>
    <!-- ================= COLLISION ================= -->
    <collision>
      <origin rpy="0 0 0" xyz="0 0 0" />
      <geometry>
        <mesh filename="/workspace/external/rh56dfx_description/meshes/left/collision/left_thumb_tip.STL" />
      </geometry>
      <material name="">
        <color rgba="1 0 0 1" />
      </material>
    </collision>
  </link>
  <!-- ================= JOINT ================= -->
  <joint name="left_thumb_tip_joint" type="fixed">
    <origin rpy="1.37938246389059 -0.0332499608948743 0.0135335445391149" xyz="0.000289440688743703 -0.0147768013355046 -0.0080365466825163" />
    <parent link="left_thumb_rubber_3" />
    <child link="left_thumb_tip" />
  </joint>
  <!-- ============================================================= -->
  <!-- INDEX 1                                                       -->
  <!-- ============================================================= -->
  <link name="left_index_1">
    <inertial>
      <origin rpy="0 0 0" xyz="0.000461541435807844 0.0116515999092932 -0.00590003371767814" />
      <mass value="0.00313593515786095" />
      <inertia ixx="4.99043606656405E-07" ixy="-3.95128282410646E-08" ixz="-5.34437774032156E-14" iyy="1.54311839890674E-07" iyz="-6.71702540608781E-12" izz="5.22966345973091E-07" />
    </inertial>
    <!-- ================= VISUAL ================= -->
    <visual>
      <origin rpy="0 0 0" xyz="0 0 0" />
      <geometry>
        <mesh filename="/workspace/external/rh56dfx_description/meshes/left/visual/left_index_1.STL" />
      </geometry>
      <material name="">
        <color rgba="1 1 1 1" />
      </material>
    </visual>
    <!-- ================= COLLISION ================= -->
    <collision>
      <origin rpy="0 0 0" xyz="0 0 0" />
      <geometry>
        <mesh filename="/workspace/external/rh56dfx_description/meshes/left/collision/left_index_1.STL" />
      </geometry>
      <material name="">
        <color rgba="1 0 0 1" />
      </material>
    </collision>
  </link>
  <!-- ================= JOINT ================= -->
  <joint name="left_index_1_joint" type="revolute">
    <origin rpy="0.034907 0 0" xyz="-0.0022453 0.10413 0.018118" />
    <parent link="left_hand_base" />
    <child link="left_index_1" />
    <axis xyz="0 0 -1" />
    <limit effort="10" lower="0" upper="1.344277" velocity="2" />
  </joint>
  <!-- ============================================================= -->
  <!-- INDEX RUBBER 1                                                -->
  <!-- ============================================================= -->
  <link name="left_index_rubber_1">
    <inertial>
      <origin rpy="0 0 0" xyz="4.68281528998027E-07 -0.000277302976287988 -0.00810702727213528" />
      <mass value="0.00100751033943594" />
      <inertia ixx="9.52671624720056E-08" ixy="1.84022397141766E-12" ixz="1.13723901975888E-12" iyy="6.33345349673424E-08" iyz="-1.10134790876878E-08" izz="8.23782108095197E-08" />
    </inertial>
    <!-- ================= VISUAL ================= -->
    <visual>
      <origin rpy="0 0 0" xyz="0 0 0" />
      <geometry>
        <mesh filename="/workspace/external/rh56dfx_description/meshes/left/visual/left_index_rubber_1.STL" />
      </geometry>
      <material name="">
        <color rgba="0.298039215686275 0.298039215686275 0.298039215686275 1" />
      </material>
    </visual>
    <!-- ================= COLLISION ================= -->
  </link>
  <!-- ================= JOINT ================= -->
  <joint name="left_index_rubber_1_joint" type="fixed">
    <origin rpy="-1.63727241823797 1.57076102968367 -1.57079632684175" xyz="0.01096212818371 0.0154754543575723 -0.00589908996829794" />
    <parent link="left_index_1" />
    <child link="left_index_rubber_1" />
  </joint>
  <!-- ============================================================= -->
  <!-- INDEX 2                                                       -->
  <!-- ============================================================= -->
  <link name="left_index_2">
    <inertial>
      <origin rpy="0 0 0" xyz="0.000846459676133171 0.0159699536063371 -0.00510110719069301" />
      <mass value="0.00329259625036443" />
      <inertia ixx="2.85619906326361E-07" ixy="-9.65833645685913E-08" ixz="1.13183640639823E-11" iyy="9.390204363466E-08" iyz="2.1481028900634E-11" izz="3.31433102179914E-07" />
    </inertial>
    <!-- ================= VISUAL ================= -->
    <visual>
      <origin rpy="0 0 0" xyz="0 0 0" />
      <geometry>
        <mesh filename="/workspace/external/rh56dfx_description/meshes/left/visual/left_index_2.STL" />
      </geometry>
      <material name="">
        <color rgba="1 1 1 1" />
      </material>
    </visual>
    <!-- ================= COLLISION ================= -->
    <collision>
      <origin rpy="0 0 0" xyz="0 0 0" />
      <geometry>
        <mesh filename="/workspace/external/rh56dfx_description/meshes/left/collision/left_index_2.STL" />
      </geometry>
      <material name="">
        <color rgba="1 0 0 1" />
      </material>
    </collision>
  </link>
  <!-- ================= JOINT ================= -->
  <joint name="left_index_2_joint" type="revolute">
    <origin rpy="0 0 0" xyz="0.00711888977031654 0.031333910351405 -0.000800000000000023" />
    <parent link="left_index_1" />
    <child link="left_index_2" />
    <axis xyz="0 0 -1" />
    <limit effort="10" lower="0" upper="1.59562" velocity="2" />
    <!-- Mimic behaviour -->
    <mimic joint="left_index_1_joint" multiplier="1.1169" offset="-0.15" />
  </joint>
  <!-- ============================================================= -->
  <!-- INDEX RUBBER 2                                                -->
  <!-- ============================================================= -->
  <link name="left_index_rubber_2">
    <inertial>
      <origin rpy="0 0 0" xyz="3.71014377972823E-06 0.0158540066839677 -0.000683115137425944" />
      <mass value="0.00119004560800986" />
      <inertia ixx="1.35899798757468E-07" ixy="8.50258176038257E-11" ixz="-8.30283954597412E-12" iyy="2.32721303061557E-08" iyz="-1.59661991933365E-08" izz="1.37431891967755E-07" />
    </inertial>
    <!-- ================= VISUAL ================= -->
    <visual>
      <origin rpy="0 0 0" xyz="0 0 0" />
      <geometry>
        <mesh filename="/workspace/external/rh56dfx_description/meshes/left/visual/left_index_rubber_2.STL" />
      </geometry>
      <material name="">
        <color rgba="0.298039215686275 0.298039215686275 0.298039215686275 1" />
      </material>
    </visual>
    <!-- ================= COLLISION ================= -->
  </link>
  <!-- ================= JOINT ================= -->
  <joint name="left_index_rubber_2_joint" type="fixed">
    <origin rpy="-1.45082090935432 1.56380581495719 -1.57079632679513" xyz="0.00701471041712752 0.0124857131697119 -0.00505570909095784" />
    <parent link="left_index_2" />
    <child link="left_index_rubber_2" />
  </joint>
  <!-- ============================================================= -->
  <!-- INDEX PAD                                                     -->
  <!-- ============================================================= -->
  <link name="left_index_pad">
    <inertial>
      <origin rpy="0 0 0" xyz="4.72282110058897E-06 -0.00107358686744947 -0.000867315001026159" />
      <mass value="1.74942869080946E-05" />
      <inertia ixx="1.97791136671661E-11" ixy="8.97449012100187E-15" ixz="-1.07077919025427E-13" iyy="2.4905734214284E-11" iyz="-1.72170853830108E-12" izz="3.95652071926162E-11" />
    </inertial>
    <!-- ================= VISUAL ================= -->
    <visual>
      <origin rpy="0 0 0" xyz="0 0 0" />
      <geometry>
        <mesh filename="/workspace/external/rh56dfx_description/meshes/left/visual/left_index_pad.STL" />
      </geometry>
      <material name="">
        <color rgba="0.298039215686275 0.298039215686275 0.298039215686275 1" />
      </material>
    </visual>
    <!-- ================= COLLISION ================= -->
    <collision>
      <origin rpy="0 0 0" xyz="0 0 0" />
      <geometry>
        <mesh filename="/workspace/external/rh56dfx_description/meshes/left/collision/left_index_pad.STL" />
      </geometry>
      <material name="">
        <color rgba="1 0 0 1" />
      </material>
    </collision>
  </link>
  <!-- ================= JOINT ================= -->
  <joint name="left_index_pad_joint" type="fixed">
    <origin rpy="0.0696904105640626 4.36438131661698E-05 0.00036202589968291" xyz="-3.002438161398E-05 0.0237882080122745 0.00562165601405612" />
    <parent link="left_index_rubber_2" />
    <child link="left_index_pad" />
  </joint>
  <!-- ============================================================= -->
  <!-- INDEX TIP                                                     -->
  <!-- ============================================================= -->
  <link name="left_index_tip">
    <inertial>
      <origin rpy="0 0 0" xyz="-0.000856665300146248 1.89922067794779E-08 -0.00102183808192999" />
      <mass value="1.72886638937717E-05" />
      <inertia ixx="2.56768040770671E-11" ixy="-3.18365589820352E-16" ixz="-2.20292569548207E-12" iyy="1.54551010736424E-11" iyz="-2.29614533759655E-16" izz="3.38497054068354E-11" />
    </inertial>
    <!-- ================= VISUAL ================= -->
    <visual>
      <origin rpy="0 0 0" xyz="0 0 0" />
      <geometry>
        <mesh filename="/workspace/external/rh56dfx_description/meshes/left/visual/left_index_tip.STL" />
      </geometry>
      <material name="">
        <color rgba="0.298039215686275 0.298039215686275 0.298039215686275 1" />
      </material>
    </visual>
    <!-- ================= COLLISION ================= -->
    <collision>
      <origin rpy="0 0 0" xyz="0 0 0" />
      <geometry>
        <mesh filename="/workspace/external/rh56dfx_description/meshes/left/collision/left_index_tip.STL" />
      </geometry>
      <material name="">
        <color rgba="1 0 0 1" />
      </material>
    </collision>
  </link>
  <!-- ================= JOINT ================= -->
  <joint name="left_index_tip_joint" type="fixed">
    <origin rpy="0.013257848934878 -1.15442763241895 -1.58292646914228" xyz="-1.30217165712487E-05 0.0312210274719897 0.00245735122592225" />
    <parent link="left_index_rubber_2" />
    <child link="left_index_tip" />
  </joint>
  <!-- ============================================================= -->
  <!-- MIDDLE 1                                                      -->
  <!-- ============================================================= -->
  <link name="left_middle_1">
    <inertial>
      <origin rpy="0 0 0" xyz="0.000461541629692849 0.0116515965600667 -0.00590004767005842" />
      <mass value="0.00313593954054027" />
      <inertia ixx="4.99044430806054E-07" ixy="-3.95130872023826E-08" ixz="1.02137723004895E-13" iyy="1.54311900293301E-07" iyz="-7.36565083300995E-12" izz="5.22966692169053E-07" />
    </inertial>
    <!-- ================= VISUAL ================= -->
    <visual>
      <origin rpy="0 0 0" xyz="0 0 0" />
      <geometry>
        <mesh filename="/workspace/external/rh56dfx_description/meshes/left/visual/left_middle_1.STL" />
      </geometry>
      <material name="">
        <color rgba="1 1 1 1" />
      </material>
    </visual>
    <!-- ================= COLLISION ================= -->
    <collision>
      <origin rpy="0 0 0" xyz="0 0 0" />
      <geometry>
        <mesh filename="/workspace/external/rh56dfx_description/meshes/left/collision/left_middle_1.STL" />
      </geometry>
      <material name="">
        <color rgba="1 0 0 1" />
      </material>
    </collision>
  </link>
  <!-- ================= JOINT ================= -->
  <joint name="left_middle_1_joint" type="revolute">
    <origin rpy="0 0 0" xyz="-0.0022453300191158 0.104699999999839 -0.00119999813570634" />
    <parent link="left_hand_base" />
    <child link="left_middle_1" />
    <axis xyz="0 0 -1" />
    <limit effort="10" lower="0" upper="1.344277" velocity="2" />
  </joint>
  <!-- ============================================================= -->
  <!-- MIDDLE RUBBER 1                                               -->
  <!-- ============================================================= -->
  <link name="left_middle_rubber_1">
    <inertial>
      <origin rpy="0 0 0" xyz="3.76241556104828E-07 -0.000277324378074262 -0.00810714899583698" />
      <mass value="0.00100751536770388" />
      <inertia ixx="9.52684579038932E-08" ixy="1.33554991989653E-12" ixz="1.04281442852275E-12" iyy="6.333529140312E-08" iyz="-1.1014346875694E-08" izz="8.2378764163469E-08" />
    </inertial>
    <!-- ================= VISUAL ================= -->
    <visual>
      <origin rpy="0 0 0" xyz="0 0 0" />
      <geometry>
        <mesh filename="/workspace/external/rh56dfx_description/meshes/left/visual/left_middle_rubber_1.STL" />
      </geometry>
      <material name="">
        <color rgba="0.298039215686275 0.298039215686275 0.298039215686275 1" />
      </material>
    </visual>
    <!-- ================= COLLISION ================= -->
  </link>
  <!-- ================= JOINT ================= -->
  <joint name="left_middle_rubber_1_joint" type="fixed">
    <origin rpy="-1.63727058353844 1.57079545855447 -1.57079632713678" xyz="0.0109621183300829 0.015475307190652 -0.00589999770412566" />
    <parent link="left_middle_1" />
    <child link="left_middle_rubber_1" />
  </joint>
  <!-- ============================================================= -->
  <!-- MIDDLE 2                                                      -->
  <!-- ============================================================= -->
  <link name="left_middle_2">
    <inertial>
      <origin rpy="0 0 0" xyz="0.00141025127204812 0.0172293351814034 -0.0051009418470411" />
      <mass value="0.0035765616038148" />
      <inertia ixx="3.58365701195062E-07" ixy="-1.25788486768389E-07" ixz="1.42327506668955E-11" iyy="1.11145569773567E-07" iyz="3.3915002379162E-11" izz="4.17351432280297E-07" />
    </inertial>
    <!-- ================= VISUAL ================= -->
    <visual>
      <origin rpy="0 0 0" xyz="0 0 0" />
      <geometry>
        <mesh filename="/workspace/external/rh56dfx_description/meshes/left/visual/left_middle_2.STL" />
      </geometry>
      <material name="">
        <color rgba="1 1 1 1" />
      </material>
    </visual>
    <!-- ================= COLLISION ================= -->
    <collision>
      <origin rpy="0 0 0" xyz="0 0 0" />
      <geometry>
        <mesh filename="/workspace/external/rh56dfx_description/meshes/left/collision/left_middle_2.STL" />
      </geometry>
      <material name="">
        <color rgba="1 0 0 1" />
      </material>
    </collision>
  </link>
  <!-- ================= JOINT ================= -->
  <joint name="left_middle_2_joint" type="revolute">
    <origin rpy="0 0 0" xyz="0.00711888977031674 0.031333910351405 -0.000800000000000023" />
    <parent link="left_middle_1" />
    <child link="left_middle_2" />
    <axis xyz="0 0 -1" />
    <limit effort="10" lower="0" upper="1.59562" velocity="2" />
    <mimic joint="left_middle_1_joint" multiplier="1.1169" offset="-0.15" />
  </joint>
  <!-- ============================================================= -->
  <!-- MIDDLE RUBBER 2                                               -->
  <!-- ============================================================= -->
  <link name="left_middle_rubber_2">
    <inertial>
      <origin rpy="0 0 0" xyz="7.72801084888974E-06 0.0179695904606754 -0.000804044743343377" />
      <mass value="0.00130495514940863" />
      <inertia ixx="1.76870136972793E-07" ixy="1.74860270573956E-10" ixz="-1.83492951193746E-11" iyy="2.53005759725665E-08" iyz="-1.81404682177571E-08" izz="1.7876054155983E-07" />
    </inertial>
    <!-- ================= VISUAL ================= -->
    <visual>
      <origin rpy="0 0 0" xyz="0 0 0" />
      <geometry>
        <mesh filename="/workspace/external/rh56dfx_description/meshes/left/visual/left_middle_rubber_2.STL" />
      </geometry>
      <material name="">
        <color rgba="0.298039215686275 0.298039215686275 0.298039215686275 1" />
      </material>
    </visual>
    <!-- ================= COLLISION ================= -->
  </link>
  <!-- ================= JOINT ================= -->
  <joint name="left_middle_rubber_2_joint" type="fixed">
    <origin rpy="-1.42206062046314 1.56574950814948 -1.57079632679496" xyz="0.00728447582116709 0.0125178675599533 -0.00500175021689153" />
    <parent link="left_middle_2" />
    <child link="left_middle_rubber_2" />
  </joint>
  <!-- ============================================================= -->
  <!-- MIDDLE PAD                                                    -->
  <!-- ============================================================= -->
  <link name="left_middle_pad">
    <inertial>
      <origin rpy="0 0 0" xyz="9.151649575323E-06 -0.000840645806262336 -0.000949482426872789" />
      <mass value="1.80772540251388E-05" />
      <inertia ixx="1.75941754992311E-11" ixy="2.77833025016142E-15" ixz="-1.92244046682768E-13" iyy="2.64975629801485E-11" iyz="-2.90926190882175E-13" izz="3.75465127391272E-11" />
    </inertial>
    <!-- ================= VISUAL ================= -->
    <visual>
      <origin rpy="0 0 0" xyz="0 0 0" />
      <geometry>
        <mesh filename="/workspace/external/rh56dfx_description/meshes/left/visual/left_middle_pad.STL" />
      </geometry>
      <material name="">
        <color rgba="0.298039215686275 0.298039215686275 0.298039215686275 1" />
      </material>
    </visual>
    <!-- ================= COLLISION ================= -->
    <collision>
      <origin rpy="0 0 0" xyz="0 0 0" />
      <geometry>
        <mesh filename="/workspace/external/rh56dfx_description/meshes/left/collision/left_middle_pad.STL" />
      </geometry>
      <material name="">
        <color rgba="1 0 0 1" />
      </material>
    </collision>
  </link>
  <!-- ================= JOINT ================= -->
  <joint name="left_middle_pad_joint" type="fixed">
    <origin rpy="-0.00517966246509127 0 -5.23567776815961E-05" xyz="-5.25438080143659E-05 0.0275018148385151 0.0054598171522955" />
    <parent link="left_middle_rubber_2" />
    <child link="left_middle_pad" />
  </joint>
  <!-- ============================================================= -->
  <!-- MIDDLE TIP                                                    -->
  <!-- ============================================================= -->
  <link name="left_middle_tip">
    <inertial>
      <origin rpy="0 0 0" xyz="-0.000704283150912199 1.7201949642498E-08 -0.00102507469949608" />
      <mass value="1.74735221647541E-05" />
      <inertia ixx="2.66254867244747E-11" ixy="-8.56607522325298E-17" ixz="-2.97431807749547E-12" iyy="1.56734895823109E-11" iyz="-1.96338363593216E-16" izz="3.33104724852485E-11" />
    </inertial>
    <!-- ================= VISUAL ================= -->
    <visual>
      <origin rpy="0 0 0" xyz="0 0 0" />
      <geometry>
        <mesh filename="/workspace/external/rh56dfx_description/meshes/left/visual/left_middle_tip.STL" />
      </geometry>
      <material name="">
        <color rgba="0.298039215686275 0.298039215686275 0.298039215686275 1" />
      </material>
    </visual>
    <!-- ================= COLLISION ================= -->
    <collision>
      <origin rpy="0 0 0" xyz="0 0 0" />
      <geometry>
        <mesh filename="/workspace/external/rh56dfx_description/meshes/left/collision/left_middle_tip.STL" />
      </geometry>
      <material name="">
        <color rgba="1 0 0 1" />
      </material>
    </collision>
  </link>
  <!-- ================= JOINT ================= -->
  <joint name="left_middle_tip_joint" type="fixed">
    <origin rpy="0.0212852224144184 -1.10096720678332 -1.5897782789153" xyz="-2.14438756649671E-05 0.0347938058137823 0.00223431434988798" />
    <parent link="left_middle_rubber_2" />
    <child link="left_middle_tip" />
  </joint>
  <!-- ============================================================= -->
  <!-- RING 1                                                        -->
  <!-- ============================================================= -->
  <link name="left_ring_1">
    <inertial>
      <origin rpy="0 0 0" xyz="0.00046149481752461 0.0116511737378717 -0.00589994851254672" />
      <mass value="0.00313603242920605" />
      <inertia ixx="4.99060820960054E-07" ixy="-3.95143745747422E-08" ixz="9.0918258040865E-14" iyy="1.54314829938476E-07" iyz="-2.76758102855439E-12" izz="5.22983831870586E-07" />
    </inertial>
    <!-- ================= VISUAL ================= -->
    <visual>
      <origin rpy="0 0 0" xyz="0 0 0" />
      <geometry>
        <mesh filename="/workspace/external/rh56dfx_description/meshes/left/visual/left_ring_1.STL" />
      </geometry>
      <material name="">
        <color rgba="1 1 1 1" />
      </material>
    </visual>
    <!-- ================= COLLISION ================= -->
    <collision>
      <origin rpy="0 0 0" xyz="0 0 0" />
      <geometry>
        <mesh filename="/workspace/external/rh56dfx_description/meshes/left/collision/left_ring_1.STL" />
      </geometry>
      <material name="">
        <color rgba="1 0 0 1" />
      </material>
    </collision>
  </link>
  <!-- ================= JOINT ================= -->
  <joint name="left_ring_1_joint" type="revolute">
    <origin rpy="-0.0523598775598309 0 0" xyz="-0.0022453318336232 0.104505254785017 -0.0204370178446974" />
    <parent link="left_hand_base" />
    <child link="left_ring_1" />
    <axis xyz="0 0 -1" />
    <limit effort="10" lower="0" upper="1.344277" velocity="2" />
  </joint>
  <!-- ============================================================= -->
  <!-- RING RUBBER 1                                                 -->
  <!-- ============================================================= -->
  <link name="left_ring_rubber_1">
    <inertial>
      <origin rpy="0 0 0" xyz="3.97260010304157E-07 -0.000277764179520239 -0.0081076194726033" />
      <mass value="0.00100758613953433" />
      <inertia ixx="9.52792767429818E-08" ixy="9.3673932045207E-13" ixz="3.62378809448717E-13" iyy="6.33418105662401E-08" iyz="-1.10190419604946E-08" izz="8.23832310585694E-08" />
    </inertial>
    <!-- ================= VISUAL ================= -->
    <visual>
      <origin rpy="0 0 0" xyz="0 0 0" />
      <geometry>
        <mesh filename="/workspace/external/rh56dfx_description/meshes/left/visual/left_ring_rubber_1.STL" />
      </geometry>
      <material name="">
        <color rgba="0.298039215686275 0.298039215686275 0.298039215686275 1" />
      </material>
    </visual>
    <!-- ================= COLLISION ================= -->
  </link>
  <!-- ================= JOINT ================= -->
  <joint name="left_ring_rubber_1_joint" type="fixed">
    <origin rpy="-1.63727058319619 1.57079545842661 -1.57079632679395" xyz="0.010962118330056 0.0154753071906455 -0.00589999770412791" />
    <parent link="left_ring_1" />
    <child link="left_ring_rubber_1" />
  </joint>
  <!-- ============================================================= -->
  <!-- RING 2                                                        -->
  <!-- ============================================================= -->
  <link name="left_ring_2">
    <inertial>
      <origin rpy="0 0 0" xyz="0.000846463894616317 0.0159699347053668 -0.0051010904739314" />
      <mass value="0.00329259763446652" />
      <inertia ixx="2.85620461419742E-07" ixy="-9.65832553004102E-08" ixz="1.14615829919027E-11" iyy="9.39020197124205E-08" iyz="2.13996414103747E-11" izz="3.3143342475777E-07" />
    </inertial>
    <!-- ================= VISUAL ================= -->
    <visual>
      <origin rpy="0 0 0" xyz="0 0 0" />
      <geometry>
        <mesh filename="/workspace/external/rh56dfx_description/meshes/left/visual/left_ring_2.STL" />
      </geometry>
      <material name="">
        <color rgba="1 1 1 1" />
      </material>
    </visual>
    <!-- ================= COLLISION ================= -->
    <collision>
      <origin rpy="0 0 0" xyz="0 0 0" />
      <geometry>
        <mesh filename="/workspace/external/rh56dfx_description/meshes/left/collision/left_ring_2.STL" />
      </geometry>
      <material name="">
        <color rgba="1 0 0 1" />
      </material>
    </collision>
  </link>
  <!-- ================= JOINT ================= -->
  <joint name="left_ring_2_joint" type="revolute">
    <origin rpy="0 0 0" xyz="0.00711888977031674 0.031333910351405 -0.000800000000000023" />
    <parent link="left_ring_1" />
    <child link="left_ring_2" />
    <axis xyz="0 0 -1" />
    <limit effort="10" lower="0" upper="1.59562" velocity="2" />
    <mimic joint="left_ring_1_joint" multiplier="1.1169" offset="-0.15" />
  </joint>
  <!-- ============================================================= -->
  <!-- RING RUBBER 2                                                 -->
  <!-- ============================================================= -->
  <link name="left_ring_rubber_2">
    <inertial>
      <origin rpy="0 0 0" xyz="0.00104284546218292 0.0157830815140177 0.00127604090326092" />
      <mass value="0.0011900510522096" />
      <inertia ixx="1.35418744149707E-07" ixy="-7.15356862405758E-09" ixz="-1.95071607592085E-09" iyy="2.93921822376163E-08" iyz="-2.9378722813243E-08" izz="1.31791666226389E-07" />
    </inertial>
    <!-- ================= VISUAL ================= -->
    <visual>
      <origin rpy="0 0 0" xyz="0 0 0" />
      <geometry>
        <mesh filename="/workspace/external/rh56dfx_description/meshes/left/visual/left_ring_rubber_2.STL" />
      </geometry>
      <material name="">
        <color rgba="0.298039215686275 0.298039215686275 0.298039215686275 1" />
      </material>
    </visual>
    <!-- ================= COLLISION ================= -->
  </link>
  <!-- ================= JOINT ================= -->
  <joint name="left_ring_rubber_2_joint" type="fixed">
    <origin rpy="1.5707963267949 1.51843644923506 1.5707963267949" xyz="0.00685339412965172 0.0123693480370854 -0.00508520214385935" />
    <parent link="left_ring_2" />
    <child link="left_ring_rubber_2" />
  </joint>
  <!-- ============================================================= -->
  <!-- RING PAD                                                      -->
  <!-- ============================================================= -->
  <link name="left_ring_pad">
    <inertial>
      <origin rpy="0 0 0" xyz="-4.94030643549692E-06 -0.00107358706632565 -0.000867313787048102" />
      <mass value="1.74942858951091E-05" />
      <inertia ixx="1.97791820297692E-11" ixy="-1.02094554854037E-14" ixz="1.13379094195E-13" iyy="2.49057330486905E-11" iyz="-1.72170092059304E-12" izz="3.956513413185E-11" />
    </inertial>
    <!-- ================= VISUAL ================= -->
    <visual>
      <origin rpy="0 0 0" xyz="0 0 0" />
      <geometry>
        <mesh filename="/workspace/external/rh56dfx_description/meshes/left/visual/left_ring_pad.STL" />
      </geometry>
      <material name="">
        <color rgba="0.298039215686275 0.298039215686275 0.298039215686275 1" />
      </material>
    </visual>
    <!-- ================= COLLISION ================= -->
    <collision>
      <origin rpy="0 0 0" xyz="0 0 0" />
      <geometry>
        <mesh filename="/workspace/external/rh56dfx_description/meshes/left/collision/left_ring_pad.STL" />
      </geometry>
      <material name="">
        <color rgba="1 0 0 1" />
      </material>
    </collision>
  </link>
  <!-- ================= JOINT ================= -->
  <joint name="left_ring_pad_joint" type="fixed">
    <origin rpy="0.193248706440358 0 -0.0666352370810103" xyz="0.00154807236433219 0.0228616868969242 0.00851055241573044" />
    <parent link="left_ring_rubber_2" />
    <child link="left_ring_pad" />
  </joint>
  <!-- ============================================================= -->
  <!-- RING TIP                                                      -->
  <!-- ============================================================= -->
  <link name="left_ring_tip">
    <inertial>
      <origin rpy="0 0 0" xyz="-0.000856665327644918 1.70945193556093E-08 -0.00102183693569345" />
      <mass value="1.72886814655676E-05" />
      <inertia ixx="2.56768444584749E-11" ixy="-3.08326142677952E-16" ixz="-2.20293053403915E-12" iyy="1.54551255925788E-11" iyz="-2.10809793762129E-16" izz="3.38497407009298E-11" />
    </inertial>
    <!-- ================= VISUAL ================= -->
    <visual>
      <origin rpy="0 0 0" xyz="0 0 0" />
      <geometry>
        <mesh filename="/workspace/external/rh56dfx_description/meshes/left/visual/left_ring_tip.STL" />
      </geometry>
      <material name="">
        <color rgba="0.298039215686275 0.298039215686275 0.298039215686275 1" />
      </material>
    </visual>
    <!-- ================= COLLISION ================= -->
    <collision>
      <origin rpy="0 0 0" xyz="0 0 0" />
      <geometry>
        <mesh filename="/workspace/external/rh56dfx_description/meshes/left/collision/left_ring_tip.STL" />
      </geometry>
      <material name="">
        <color rgba="1 0 0 1" />
      </material>
    </collision>
  </link>
  <!-- ================= JOINT ================= -->
  <joint name="left_ring_tip_joint" type="fixed">
    <origin rpy="-0.0109233493860337 -1.03087334028373 -1.62695251466279" xyz="0.0020441281919974 0.0306119852979382 0.00628642959658904" />
    <parent link="left_ring_rubber_2" />
    <child link="left_ring_tip" />
  </joint>
  <!-- ============================================================= -->
  <!-- LITTLE 1                                                      -->
  <!-- ============================================================= -->
  <link name="left_little_1">
    <inertial>
      <origin rpy="0 0 0" xyz="0.000461475145813836 0.0116511477169123 -0.00589994431843399" />
      <mass value="0.00313603875974869" />
      <inertia ixx="4.99061732632513E-07" ixy="-3.95150807555593E-08" ixz="3.29643374362596E-13" iyy="1.54315415119772E-07" iyz="-2.68499196384908E-12" izz="5.22985239082346E-07" />
    </inertial>
    <!-- ================= VISUAL ================= -->
    <visual>
      <origin rpy="0 0 0" xyz="0 0 0" />
      <geometry>
        <mesh filename="/workspace/external/rh56dfx_description/meshes/left/visual/left_little_1.STL" />
      </geometry>
      <material name="">
        <color rgba="1 1 1 1" />
      </material>
    </visual>
    <!-- ================= COLLISION ================= -->
    <collision>
      <origin rpy="0 0 0" xyz="0 0 0" />
      <geometry>
        <mesh filename="/workspace/external/rh56dfx_description/meshes/left/collision/left_little_1.STL" />
      </geometry>
      <material name="">
        <color rgba="1 0 0 1" />
      </material>
    </collision>
  </link>
  <!-- ================= JOINT ================= -->
  <joint name="left_little_1_joint" type="revolute">
    <origin rpy="-0.104719755119647 0 0" xyz="-0.00224533363585604 0.103303988639843 -0.0396374817119981" />
    <parent link="left_hand_base" />
    <child link="left_little_1" />
    <axis xyz="0 0 -1" />
    <limit effort="10" lower="0" upper="1.344277" velocity="2" />
  </joint>
  <!-- ============================================================= -->
  <!-- LITTLE RUBBER 1                                               -->
  <!-- ============================================================= -->
  <link name="left_little_rubber_1">
    <inertial>
      <origin rpy="0 0 0" xyz="3.96620438825046E-07 -0.000277753553895421 -0.00810761573399517" />
      <mass value="0.00100758679674637" />
      <inertia ixx="9.52792952312133E-08" ixy="9.76259542731449E-13" ixz="3.4017888649422E-13" iyy="6.33417954922802E-08" iyz="-1.10190612465513E-08" izz="8.23833417446055E-08" />
    </inertial>
    <!-- ================= VISUAL ================= -->
    <visual>
      <origin rpy="0 0 0" xyz="0 0 0" />
      <geometry>
        <mesh filename="/workspace/external/rh56dfx_description/meshes/left/visual/left_little_rubber_1.STL" />
      </geometry>
      <material name="">
        <color rgba="0.298039215686275 0.298039215686275 0.298039215686275 1" />
      </material>
    </visual>
    <!-- ================= COLLISION ================= -->
  </link>
  <!-- ================= JOINT ================= -->
  <joint name="left_little_rubber_1_joint" type="fixed">
    <origin rpy="-1.63727058315032 1.57079545829877 -1.57079632674945" xyz="0.0109621183302624 0.0154753071907081 -0.0058999977041195" />
    <parent link="left_little_1" />
    <child link="left_little_rubber_1" />
  </joint>
  <!-- ============================================================= -->
  <!-- LITTLE 2                                                      -->
  <!-- ============================================================= -->
  <link name="left_little_2">
    <inertial>
      <origin rpy="0 0 0" xyz="-9.66953409735488E-05 0.0131703851115681 -0.0051009352074308" />
      <mass value="0.00261913175532863" />
      <inertia ixx="1.61202126201402E-07" ixy="-4.97996992197648E-08" ixz="7.72395884071146E-12" iyy="6.22418447396845E-08" iyz="1.70585616369544E-11" izz="1.85396555993052E-07" />
    </inertial>
    <!-- ================= VISUAL ================= -->
    <visual>
      <origin rpy="0 0 0" xyz="0 0 0" />
      <geometry>
        <mesh filename="/workspace/external/rh56dfx_description/meshes/left/visual/left_little_2.STL" />
      </geometry>
      <material name="">
        <color rgba="1 1 1 1" />
      </material>
    </visual>
    <!-- ================= COLLISION ================= -->
    <collision>
      <origin rpy="0 0 0" xyz="0 0 0" />
      <geometry>
        <mesh filename="/workspace/external/rh56dfx_description/meshes/left/collision/left_little_2.STL" />
      </geometry>
      <material name="">
        <color rgba="1 0 0 1" />
      </material>
    </collision>
  </link>
  <!-- ================= JOINT ================= -->
  <joint name="left_little_2_joint" type="revolute">
    <origin rpy="0 0 0" xyz="0.00711888977031677 0.0313339103514049 -0.000799999999999995" />
    <parent link="left_little_1" />
    <child link="left_little_2" />
    <axis xyz="0 0 -1" />
    <limit effort="10" lower="0" upper="1.59562" velocity="2" />
    <mimic joint="left_little_1_joint" multiplier="1.1169" offset="-0.15" />
  </joint>
  <!-- ============================================================= -->
  <!-- LITTLE RUBBER 2                                               -->
  <!-- ============================================================= -->
  <link name="left_little_rubber_2">
    <inertial>
      <origin rpy="0 0 0" xyz="7.99800886075452E-08 0.0112749035859891 -0.000128893404753347" />
      <mass value="0.000944677110750505" />
      <inertia ixx="7.27256998745925E-08" ixy="8.7944783960686E-12" ixz="-4.11179878788431E-13" iyy="1.9751675428608E-08" iyz="-1.31114374351836E-08" izz="7.28078257130206E-08" />
    </inertial>
    <!-- ================= VISUAL ================= -->
    <visual>
      <origin rpy="0 0 0" xyz="0 0 0" />
      <geometry>
        <mesh filename="/workspace/external/rh56dfx_description/meshes/left/visual/left_little_rubber_2.STL" />
      </geometry>
      <material name="">
        <color rgba="0.298039215686275 0.298039215686275 0.298039215686275 1" />
      </material>
    </visual>
    <!-- ================= COLLISION ================= -->
  </link>
  <!-- ================= JOINT ================= -->
  <joint name="left_little_rubber_2_joint" type="fixed">
    <origin rpy="3.14068811224663 1.57007206953461 3.13379721155807" xyz="0.00605975881840989 0.0120279982928333 -0.00510001089644316" />
    <parent link="left_little_2" />
    <child link="left_little_rubber_2" />
  </joint>
  <!-- ============================================================= -->
  <!-- LITTLE PAD                                                    -->
  <!-- ============================================================= -->
  <link name="left_little_pad">
    <inertial>
      <origin rpy="0 0 0" xyz="4.26351731697139E-09 -0.000945394972293657 -0.000793541046852683" />
      <mass value="1.46539353671065E-05" />
      <inertia ixx="1.40180735091283E-11" ixy="1.61934642095291E-17" ixz="1.17587638114365E-16" iyy="2.05087141535222E-11" iyz="-1.09095131218755E-12" izz="3.10123565645623E-11" />
    </inertial>
    <!-- ================= VISUAL ================= -->
    <visual>
      <origin rpy="0 0 0" xyz="0 0 0" />
      <geometry>
        <mesh filename="/workspace/external/rh56dfx_description/meshes/left/visual/left_little_pad.STL" />
      </geometry>
      <material name="">
        <color rgba="0.298039215686275 0.298039215686275 0.298039215686275 1" />
      </material>
    </visual>
    <!-- ================= COLLISION ================= -->
    <collision>
      <origin rpy="0 0 0" xyz="0 0 0" />
      <geometry>
        <mesh filename="/workspace/external/rh56dfx_description/meshes/left/collision/left_little_pad.STL" />
      </geometry>
      <material name="">
        <color rgba="1 0 0 1" />
      </material>
    </collision>
  </link>
  <!-- ================= JOINT ================= -->
  <joint name="left_little_pad_joint" type="fixed">
    <origin rpy="0.234319162085704 -0.000724253436295822 0" xyz="0 0.0158106591438754 0.00622450775451257" />
    <parent link="left_little_rubber_2" />
    <child link="left_little_pad" />
  </joint>
  <!-- ============================================================= -->
  <!-- LITTLE TIP                                                    -->
  <!-- ============================================================= -->
  <link name="left_little_tip">
    <inertial>
      <origin rpy="0 0 0" xyz="-0.000679511004398545 -7.33584859524683E-09 -0.0009899693704125" />
      <mass value="1.82383852219562E-05" />
      <inertia ixx="2.78570131965694E-11" ixy="-6.23802723798247E-17" ixz="-2.37868618847864E-12" iyy="1.66773044526593E-11" iyz="4.01471577675434E-17" izz="3.57549531689912E-11" />
    </inertial>
    <!-- ================= VISUAL ================= -->
    <visual>
      <origin rpy="0 0 0" xyz="0 0 0" />
      <geometry>
        <mesh filename="/workspace/external/rh56dfx_description/meshes/left/visual/left_little_tip.STL" />
      </geometry>
      <material name="">
        <color rgba="0.298039215686275 0.298039215686275 0.298039215686275 1" />
      </material>
    </visual>
    <!-- ================= COLLISION ================= -->
    <collision>
      <origin rpy="0 0 0" xyz="0 0 0" />
      <geometry>
        <mesh filename="/workspace/external/rh56dfx_description/meshes/left/collision/left_little_tip.STL" />
      </geometry>
      <material name="">
        <color rgba="1 0 0 1" />
      </material>
    </collision>
  </link>
  <!-- ================= JOINT ================= -->
  <joint name="left_little_tip_joint" type="fixed">
    <origin rpy="0.00195594039193604 -1.19148436669212 -1.57261259196533" xyz="0 0.0235281291193634 0.00364792987438493" />
    <parent link="left_little_rubber_2" />
    <child link="left_little_tip" />
  </joint>
  <!-- ============================================================= -->
  <!-- PALM                                                          -->
  <!-- ============================================================= -->
  <link name="left_palm">
    <inertial>
      <origin rpy="0 0 0" xyz="0.0048754084307947 -0.00792635358921372 0.000407295131145555" />
      <mass value="0.0103867697224328" />
      <inertia ixx="4.32579238773537E-06" ixy="1.82986381074143E-06" ixz="-1.24431557170631E-07" iyy="5.02135147678096E-06" iyz="6.0880720395417E-07" izz="9.01588192510949E-06" />
    </inertial>
    <!-- ================= VISUAL ================= -->
    <visual>
      <origin rpy="0 0 0" xyz="0 0 0" />
      <geometry>
        <mesh filename="/workspace/external/rh56dfx_description/meshes/left/visual/left_palm.STL" />
      </geometry>
      <material name="">
        <color rgba="0.298039215686275 0.298039215686275 0.298039215686275 1" />
      </material>
    </visual>
    <!-- ================= COLLISION ================= -->
    <collision>
      <origin rpy="0 0 0" xyz="0 0 0" />
      <geometry>
        <mesh filename="/workspace/external/rh56dfx_description/meshes/left/collision/left_palm.STL" />
      </geometry>
      <material name="">
        <color rgba="1 0 0 1" />
      </material>
    </collision>
  </link>
  <!-- ================= JOINT ================= -->
  <joint name="left_palm_joint" type="fixed">
    <origin rpy="3.14159265242298 1.57079623022433 3.14159265242298" xyz="0.0124026678056337 0.0690814278199097 -0.0185014368261144" />
    <parent link="left_hand_base" />
    <child link="left_palm" />
  </joint>
</robot>
