<?xml version="1.0" ?>
<!-- =================================================================================== -->
<!-- |    This document was autogenerated by xacro from /tmp/rh56dfx_urdf_pd3ju9ij/rh56dfx_wrapper.xacro | -->
<!-- |    EDITING THIS FILE BY HAND IS NOT RECOMMENDED                                 | -->
<!-- =================================================================================== -->
<robot name="rh56dfx">
  <!--
  ======================================================================
  INSPIRE HAND RH56DFX - PARAMETRIC MACRO
  ======================================================================
  -->
  <!-- ============================================================= -->
  <!-- MESH ROOT DIRECTORY                                           -->
  <!-- ============================================================= -->
  <!-- ============================================================= -->
  <!--     WRIST BASE LINK                                           -->
  <!-- ============================================================= -->
  <link name="right_wrist_base_link">
    <!-- ================= INERTIAL ================= -->
    <inertial>
      <origin rpy="0 0 0" xyz="0.00191998775838077 -2.17534676938413E-08 0.0332314674517473"/>
      <mass value="0.0695038666375085"/>
      <inertia ixx="3.02480603452712E-05" ixy="-6.93925958512878E-11" ixz="5.01503749466725E-07" iyy="3.10214964795132E-05" iyz="-1.99074603834946E-11" izz="2.86515789056302E-05"/>
    </inertial>
    <!-- ================= VISUAL ================= -->
    <visual>
      <origin rpy="0 0 0" xyz="0 0 0"/>
      <geometry>
        <mesh filename="/workspace/external/rh56dfx_description/meshes/right/visual/right_wrist_base_link.STL"/>
      </geometry>
      <material name="">
        <color rgba="1 1 1 1"/>
      </material>
    </visual>
    <!-- ================= COLLISION ================= -->
    <collision>
      <origin rpy="0 0 0" xyz="0 0 0"/>
      <geometry>
        <mesh filename="/workspace/external/rh56dfx_description/meshes/right/collision/right_wrist_base_link.STL"/>
      </geometry>
      <material name="">
        <color rgba="1 0 0 1"/>
      </material>
    </collision>
  </link>
  <!-- ========================================================= -->
  <!-- Wrist yaw joint                                          -->
  <!-- ========================================================= -->
  <link name="right_wrist_yaw">
    <!-- ================= INERTIAL ================= -->
    <inertial>
      <origin rpy="0 0 0" xyz="3.75516494205945E-11 0.00545897820466844 0.0131919971923186"/>
      <mass value="0.0027789058545723"/>
      <inertia ixx="2.26417228011718E-07" ixy="-1.56095341004759E-16" ixz="5.38481373178298E-16" iyy="1.49079739934158E-07" iyz="1.48845839380448E-08" izz="1.09370485183286E-07"/>
    </inertial>
    <!-- ================= VISUAL ================= -->
    <visual>
      <origin rpy="0 0 0" xyz="0 0 0"/>
      <geometry>
        <mesh filename="/workspace/external/rh56dfx_description/meshes/right/visual/right_wrist_yaw.STL"/>
      </geometry>
      <material name="">
        <color rgba="1 1 1 1"/>
      </material>
    </visual>
    <!-- ================= COLLISION ================= -->
    <collision>
      <origin rpy="0 0 0" xyz="0 0 0"/>
      <geometry>
        <mesh filename="/workspace/external/rh56dfx_description/meshes/right/collision/right_wrist_yaw.STL"/>
      </geometry>
      <material name="">
        <color rgba="1 0 0 1"/>
      </material>
      <material name="">
        <color rgba="1 0 0 1"/>
      </material>
    </collision>
  </link>
  <joint name="right_wrist_yaw_joint" type="revolute">
    <!-- ================= ORIGIN ================= -->
    <origin rpy="1.5708 0 1.5708" xyz="-0.0055 0 0.0785"/>
    <parent link="right_wrist_base_link"/>
    <child link="right_wrist_yaw"/>
    <axis xyz="0 0 -1"/>
    <!-- ================= LIMITS ================= -->
    <limit effort="10" lower="-0.445" upper="0.445" velocity="2"/>
  </joint>
  <!-- ========================================================= -->
  <!-- Hand base (palm carrier)                                  -->
  <!-- ========================================================= -->
  <link name="right_hand_base">
    <!-- ================= INERTIAL ================= -->
    <inertial>
      <origin rpy="0 0 0" xyz="0.00186701184983107 0.0342512668966462 0.0144068752323911"/>
      <mass value="0.175357386592075"/>
      <inertia ixx="0.000329494407160081" ixy="1.91477414348783E-06" ixz="-1.39936390260134E-06" iyy="0.000194341011884896" iyz="1.21251307175976E-06" izz="0.000213768215595836"/>
    </inertial>
    <!-- ================= VISUAL ================= -->
    <visual>
      <origin rpy="0 0 0" xyz="0 0 0"/>
      <geometry>
        <mesh filename="/workspace/external/rh56dfx_description/meshes/right/visual/right_hand_base.STL"/>
      </geometry>
      <material name="">
        <color rgba="1 1 1 1"/>
      </material>
    </visual>
    <!-- ================= COLLISION ================= -->
    <collision>
      <origin rpy="0 0 0" xyz="0 0 0"/>
      <geometry>
        <mesh filename="/workspace/external/rh56dfx_description/meshes/right/collision/right_hand_base.STL"/>
      </geometry>
      <material name="">
        <color rgba="1 0 0 1"/>
      </material>
      <material name="">
        <color rgba="1 0 0 1"/>
      </material>
    </collision>
  </link>
  <joint name="right_hand_base_joint" type="revolute">
    <!-- ================= ORIGIN ================= -->
    <origin rpy="3.1414 1.5708 3.1414" xyz="-0.015 0 0.0055"/>
    <parent link="right_wrist_yaw"/>
    <child link="right_hand_base"/>
    <axis xyz="0 0 -1"/>
    <!-- ================= LIMITS ================= -->
    <limit effort="10" lower="-0.3955" upper="0.386" velocity="2"/>
  </joint>
  <!-- ========================================================= -->
  <!-- Fingers: thumb, index, middle, ring, little               -->
  <!-- ========================================================= -->
  <!--
    Mimic joints:
      - Used to reduce control dimensionality
      - Required for realistic finger curling
  -->
  <!-- THUMB -->
  <!-- right_thumb_1, right_thumb_2, ... -->
  <!-- index finger -->
  <!-- middle finger -->
  <!-- ring finger -->
  <!-- little finger -->
  <!-- ============================================================= -->
  <!-- THUMB 1                                                       -->
  <!-- ============================================================= -->
  <link name="right_thumb_1">
    <!-- ================= INERTIAL ================= -->
    <inertial>
      <origin rpy="0 0 0" xyz="0.000675361243917746 0.00433554414064959 -0.00508779581139575"/>
      <mass value="0.00485414527400047"/>
      <inertia ixx="1.9609332795642E-07" ixy="-3.48579868905759E-08" ixz="-3.39216862091962E-09" iyy="1.43278320785818E-07" iyz="-8.19845149663523E-09" izz="1.68937481009729E-07"/>
    </inertial>
    <!-- ================= VISUAL ================= -->
    <visual>
      <origin rpy="0 0 0" xyz="0 0 0"/>
      <geometry>
        <mesh filename="/workspace/external/rh56dfx_description/meshes/right/visual/right_thumb_1.STL"/>
      </geometry>
      <material name="">
        <color rgba="1 1 1 1"/>
      </material>
    </visual>
    <!-- ================= COLLISION ================= -->
    <collision>
      <origin rpy="0 0 0" xyz="0 0 0"/>
      <geometry>
        <mesh filename="/workspace/external/rh56dfx_description/meshes/right/collision/right_thumb_1.STL"/>
      </geometry>
      <material name="">
        <color rgba="1 0 0 1"/>
      </material>
      <material name="">
        <color rgba="1 0 0 1"/>
      </material>
    </collision>
  </link>
  <joint name="right_thumb_1_joint" type="revolute">
    <!-- ================= ORIGIN ================= -->
    <origin rpy="1.5707963267949 0 -3.14159265358979" xyz="-0.0153000040088447 0.0343000000007003 0.036400000219911"/>
    <parent link="right_hand_base"/>
    <child link="right_thumb_1"/>
    <axis xyz="0 0 -1"/>
    <!-- ================= LIMITS ================= -->
    <limit effort="10" lower="0" upper="1.310384" velocity="2"/>
  </joint>
  <!-- ============================================================= -->
  <!-- THUMB 2.                                                      -->
  <!-- ============================================================= -->
  <link name="right_thumb_2">
    <!-- ================= INERTIAL ================= -->
    <inertial>
      <origin rpy="0 0 0" xyz="-0.021702059702569 0.0140073366357873 0.00802385604823092"/>
      <mass value="0.011197324573215"/>
      <inertia ixx="4.77080502997218E-06" ixy="2.24565380204443E-06" ixz="-1.93384804492673E-09" iyy="5.25070317061785E-06" iyz="-6.93473068910724E-10" izz="9.41384151324246E-06"/>
    </inertial>
    <!-- ================= VISUAL ================= -->
    <visual>
      <origin rpy="0 0 0" xyz="0 0 0"/>
      <geometry>
        <mesh filename="/workspace/external/rh56dfx_description/meshes/right/visual/right_thumb_2.STL"/>
      </geometry>
      <material name="">
        <color rgba="1 1 1 1"/>
      </material>
    </visual>
    <!-- ================= COLLISION ================= -->
    <collision>
      <origin rpy="0 0 0" xyz="0 0 0"/>
      <geometry>
        <mesh filename="/workspace/external/rh56dfx_description/meshes/right/collision/right_thumb_2.STL"/>
      </geometry>
      <material name="">
        <color rgba="1 0 0 1"/>
      </material>
    </collision>
  </link>
  <joint name="right_thumb_2_joint" type="revolute">
    <!-- ================= ORIGIN ================= -->
    <origin rpy="1.5707963267949 0 -1.83259571459404" xyz="0.0107038256289915 0.00903759464150421 -0.00649999999999998"/>
    <axis xyz="0 0 -1"/>
    <parent link="right_thumb_1"/>
    <child link="right_thumb_2"/>
    <limit effort="10" lower="0" upper="0.523477" velocity="2"/>
  </joint>
  <!-- ============================================================= -->
  <!-- THUMB RUBBER 1                                                -->
  <!-- ============================================================= -->
  <link name="right_thumb_rubber_1">
    <inertial>
      <origin rpy="0 0 0" xyz="5.25123796278198E-05 -0.00265158184532596 -0.00524156527611314"/>
      <mass value="0.00149071340727244"/>
      <inertia ixx="1.88775194707542E-07" ixy="6.69255450795096E-11" ixz="-4.00394969226025E-10" iyy="8.68614474046453E-08" iyz="-3.72017830861924E-09" izz="2.26648080388043E-07"/>
    </inertial>
    <!-- ============================================================ -->
    <!-- ================= VISUAL ================= -->
    <visual>
      <origin rpy="0 0 0" xyz="0 0 0"/>
      <geometry>
        <mesh filename="/workspace/external/rh56dfx_description/meshes/right/visual/right_thumb_rubber_1.STL"/>
      </geometry>
      <material name="">
        <color rgba="0.298039215686275 0.298039215686275 0.298039215686275 1"/>
      </material>
    </visual>
    <!-- ================= COLLISION ================= -->
    <collision>
      <origin rpy="0 0 0" xyz="0 0 0"/>
      <geometry>
        <mesh filename="/workspace/external/rh56dfx_description/meshes/right/collision/right_thumb_rubber_1.STL"/>
      </geometry>
      <material name="">
        <color rgba="1 0 0 1"/>
      </material>
    </collision>
  </link>
  <!-- ================= JOINT ================= -->
  <joint name="right_thumb_rubber_1_joint" type="fixed">
    <origin rpy="-3.13815940276514 1.56040994467676 -2.19148660953744" xyz="-0.013046553810162 0.0313855611442986 0.00799913310995912"/>
    <parent link="right_thumb_2"/>
    <child link="right_thumb_rubber_1"/>
  </joint>
  <!-- ============================================================= -->
  <!-- THUMB 3                                                       -->
  <!-- ============================================================= -->
  <link name="right_thumb_3">
    <inertial>
      <origin rpy="0 0 0" xyz="-0.00916388835013904 -0.000213690008193602 0.00750028797357696"/>
      <mass value="0.00637737480666728"/>
      <inertia ixx="7.06810039556575E-07" ixy="1.8064821102149E-07" ixz="-7.56321985719409E-12" iyy="5.60101216987723E-07" iyz="6.09546956255714E-12" izz="8.41964957548188E-07"/>
    </inertial>
    <!-- ============================================================ -->
    <!-- ================= VISUAL ================= -->
    <visual>
      <origin rpy="0 0 0" xyz="0 0 0"/>
      <geometry>
        <mesh filename="/workspace/external/rh56dfx_description/meshes/right/visual/right_thumb_3.STL"/>
      </geometry>
      <material name="">
        <color rgba="1 1 1 1"/>
      </material>
    </visual>
    <!-- ================= COLLISION ================= -->
    <collision>
      <origin rpy="0 0 0" xyz="0 0 0"/>
      <geometry>
        <mesh filename="/workspace/external/rh56dfx_description/meshes/right/collision/right_thumb_3.STL"/>
      </geometry>
      <material name="">
        <color rgba="1 0 0 1"/>
      </material>
    </collision>
  </link>
  <!-- ================= JOINT ================= -->
  <joint name="right_thumb_3_joint" type="revolute">
    <origin rpy="0 0 0" xyz="-0.0415838804016112 0.0375080548719081 0.00050000000000007"/>
    <axis xyz="0 0 -1"/>
    <parent link="right_thumb_2"/>
    <child link="right_thumb_3"/>
    <limit effort="10" lower="0" upper="0.606844" velocity="2"/>
    <!-- Mimic remains identical for both sides -->
    <mimic joint="right_thumb_2_joint" multiplier="1.1425" offset="0"/>
  </joint>
  <!-- ============================================================= -->
  <!-- THUMB RUBBER 2                                                -->
  <!-- ============================================================= -->
  <link name="right_thumb_rubber_2">
    <inertial>
      <origin rpy="0 0 0" xyz="0.000157140889199783 0.00288556596888331 -0.0090540619335797"/>
      <mass value="0.000712293475130305"/>
      <inertia ixx="4.20891301155909E-08" ixy="-1.40469831307447E-10" ixz="1.37381961636702E-10" iyy="5.19654488817118E-08" iyz="8.47531049325098E-09" izz="3.43756130398348E-08"/>
    </inertial>
    <!-- ================= VISUAL ================= -->
    <visual>
      <origin rpy="0 0 0" xyz="0 0 0"/>
      <geometry>
        <mesh filename="/workspace/external/rh56dfx_description/meshes/right/visual/right_thumb_rubber_2.STL"/>
      </geometry>
      <material name="">
        <color rgba="0.298039215686275 0.298039215686275 0.298039215686275 1"/>
      </material>
    </visual>
    <!-- ================= COLLISION ================= -->
    <collision>
      <origin rpy="0 0 0" xyz="0 0 0"/>
      <geometry>
        <mesh filename="/workspace/external/rh56dfx_description/meshes/right/collision/right_thumb_rubber_2.STL"/>
      </geometry>
      <material name="">
        <color rgba="1 0 0 1"/>
      </material>
    </collision>
  </link>
  <!-- ================= JOINT ================= -->
  <joint name="right_thumb_rubber_2_joint" type="fixed">
    <origin rpy="-3.14159264398177 1.55312580635649 -2.09404843013331" xyz="-0.00507003292533311 0.0118736037354007 0.00749998784521028"/>
    <parent link="right_thumb_3"/>
    <child link="right_thumb_rubber_2"/>
  </joint>
  <!-- ============================================================= -->
  <!-- THUMB 4                                                       -->
  <!-- ============================================================= -->
  <link name="right_thumb_4">
    <inertial>
      <origin rpy="0 0 0" xyz="-0.00556381960339052 0.00321786469032558 0.00598762142813954"/>
      <mass value="0.000889838221404847"/>
      <inertia ixx="2.7865190017362E-08" ixy="1.6746511102932E-08" ixz="3.94753258813809E-11" iyy="2.7870091174862E-08" iyz="9.78353772270236E-11" izz="4.65705162837952E-08"/>
    </inertial>
    <!-- ================= VISUAL ================= -->
    <visual>
      <origin rpy="0 0 0" xyz="0 0 0"/>
      <geometry>
        <mesh filename="/workspace/external/rh56dfx_description/meshes/right/visual/right_thumb_4.STL"/>
      </geometry>
      <material name="">
        <color rgba="1 1 1 1"/>
      </material>
    </visual>
    <!-- ================= COLLISION ================= -->
    <collision>
      <origin rpy="0 0 0" xyz="0 0 0"/>
      <geometry>
        <mesh filename="/workspace/external/rh56dfx_description/meshes/right/collision/right_thumb_4.STL"/>
      </geometry>
      <material name="">
        <color rgba="1 0 0 1"/>
      </material>
    </collision>
  </link>
  <!-- ================= JOINT ================= -->
  <joint name="right_thumb_4_joint" type="revolute">
    <origin rpy="0 0 0" xyz="-0.018393 0.013222 0.0015"/>
    <axis xyz="0 0 -1"/>
    <parent link="right_thumb_3"/>
    <child link="right_thumb_4"/>
    <limit effort="10" lower="0" upper="0.430866" velocity="2"/>
    <mimic joint="right_thumb_3_joint" multiplier="0.7508" offset="0"/>
  </joint>
  <!-- ============================================================= -->
  <!-- THUMB RUBBER 3                                                -->
  <!-- ============================================================= -->
  <link name="right_thumb_rubber_3">
    <inertial>
      <origin rpy="0 0 0" xyz="0.000133677754111619 0.00249789544313434 -0.00737807315210834"/>
      <mass value="0.00232428277409971"/>
      <inertia ixx="1.1738940345995E-07" ixy="1.33164031093727E-10" ixz="5.42230494538498E-12" iyy="6.71016287130116E-08" iyz="-7.29911404958279E-09" izz="1.17101548394252E-07"/>
    </inertial>
    <!-- ================= VISUAL ================= -->
    <visual>
      <origin rpy="0 0 0" xyz="0 0 0"/>
      <geometry>
        <mesh filename="/workspace/external/rh56dfx_description/meshes/right/visual/right_thumb_rubber_3.STL"/>
      </geometry>
      <material name="">
        <color rgba="0.298039215686275 0.298039215686275 0.298039215686275 1"/>
      </material>
    </visual>
    <!-- ================= COLLISION ================= -->
    <collision>
      <origin rpy="0 0 0" xyz="0 0 0"/>
      <geometry>
        <mesh filename="/workspace/external/rh56dfx_description/meshes/right/collision/right_thumb_rubber_3.STL"/>
      </geometry>
      <material name="">
        <color rgba="1 0 0 1"/>
      </material>
    </collision>
  </link>
  <!-- ================= JOINT ================= -->
  <joint name="right_thumb_rubber_3_joint" type="fixed">
    <origin rpy="-3.1415 1.5526 -2.5499" xyz="-0.001618 0.009709 0.006"/>
    <parent link="right_thumb_4"/>
    <child link="right_thumb_rubber_3"/>
  </joint>
  <!-- ============================================================= -->
  <!-- THUMB PAD                                                     -->
  <!-- ============================================================= -->
  <link name="right_thumb_pad">
    <inertial>
      <origin rpy="0 0 0" xyz="-3.17863613624736E-08 -0.00152836456065816 -0.0014060654960278"/>
      <mass value="0.000138969107299723"/>
      <inertia ixx="3.88380090334865E-10" ixy="-2.2040272967494E-15" ixz="3.72337458984265E-15" iyy="2.48185589616352E-10" iyz="-1.23321553256561E-11" izz="5.07570387988192E-10"/>
    </inertial>
    <!-- ================= VISUAL ================= -->
    <visual>
      <origin rpy="0 0 0" xyz="0 0 0"/>
      <geometry>
        <mesh filename="/workspace/external/rh56dfx_description/meshes/right/visual/right_thumb_pad.STL"/>
      </geometry>
      <material name="">
        <color rgba="0.298039215686275 0.298039215686275 0.298039215686275 1"/>
      </material>
    </visual>
    <!-- ================= COLLISION ================= -->
    <collision>
      <origin rpy="0 0 0" xyz="0 0 0"/>
      <geometry>
        <mesh filename="/workspace/external/rh56dfx_description/meshes/right/collision/right_thumb_pad.STL"/>
      </geometry>
      <material name="">
        <color rgba="1 0 0 1"/>
      </material>
    </collision>
  </link>
  <!-- ================= JOINT ================= -->
  <joint name="right_thumb_pad_joint" type="fixed">
    <origin rpy="-0.32308105919377 -0.0181645215163438 1.44824432616579E-05" xyz="1.97306155155508E-05 0.00787683873056354 -0.00108764909180575"/>
    <parent link="right_thumb_rubber_3"/>
    <child link="right_thumb_pad"/>
  </joint>
  <!-- ============================================================= -->
  <!-- THUMB TIP                                                     -->
  <!-- ============================================================= -->
  <link name="right_thumb_tip">
    <inertial>
      <origin rpy="0 0 0" xyz="-2.47505902372935E-05 0.00144636195662112 -0.00180325741638071"/>
      <mass value="0.00017110035356973"/>
      <inertia ixx="5.03295308586156E-10" ixy="1.1038459890022E-12" ixz="1.06224755236763E-12" iyy="3.76514497106408E-10" iyz="8.13921166925614E-11" izz="5.79466758416002E-10"/>
    </inertial>
    <!-- ================= VISUAL ================= -->
    <visual>
      <origin rpy="0 0 0" xyz="0 0 0"/>
      <geometry>
        <mesh filename="/workspace/external/rh56dfx_description/meshes/right/visual/right_thumb_tip.STL"/>
      </geometry>
      <material name="">
        <color rgba="0.298039215686275 0.298039215686275 0.298039215686275 1"/>
      </material>
    </visual>
    <!-- ================= COLLISION ================= -->
    <collision>
      <origin rpy="0 0 0" xyz="0 0 0"/>
      <geometry>
        <mesh filename="/workspace/external/rh56dfx_description/meshes/right/collision/right_thumb_tip.STL"/>
      </geometry>
      <material name="">
        <color rgba="1 0 0 1"/>
      </material>
    </collision>
  </link>
  <!-- ================= JOINT ================= -->
  <joint name="right_thumb_tip_joint" type="fixed">
    <origin rpy="-1.34664653486349 -0.0211118546108423 0.0134662732683287" xyz="0.000137071096497604 0.0150376112085459 -0.00754156328997224"/>
    <parent link="right_thumb_rubber_3"/>
    <child link="right_thumb_tip"/>
  </joint>
  <!-- ============================================================= -->
  <!-- INDEX 1                                                       -->
  <!-- ============================================================= -->
  <link name="right_index_1">
    <inertial>
      <origin rpy="0 0 0" xyz="0.000461509522881251 0.0116512167073588 0.00590005205650069"/>
      <mass value="0.00313593515786095"/>
      <inertia ixx="4.99043606656405E-07" ixy="-1.11033984168461E-07" ixz="-3.45534140604099E-13" iyy="1.54311839890674E-07" iyz="-8.02588111503433E-12" izz="5.22966345973091E-07"/>
    </inertial>
    <!-- ================= VISUAL ================= -->
    <visual>
      <origin rpy="0 0 0" xyz="0 0 0"/>
      <geometry>
        <mesh filename="/workspace/external/rh56dfx_description/meshes/right/visual/right_index_1.STL"/>
      </geometry>
      <material name="">
        <color rgba="1 1 1 1"/>
      </material>
    </visual>
    <!-- ================= COLLISION ================= -->
    <collision>
      <origin rpy="0 0 0" xyz="0 0 0"/>
      <geometry>
        <mesh filename="/workspace/external/rh56dfx_description/meshes/right/collision/right_index_1.STL"/>
      </geometry>
      <material name="">
        <color rgba="1 0 0 1"/>
      </material>
    </collision>
  </link>
  <!-- ================= JOINT ================= -->
  <joint name="right_index_1_joint" type="revolute">
    <origin rpy="-3.14159265358979 0 3.14159265358979" xyz="0.00194532821464022 0.10413 0.048117784"/>
    <parent link="right_hand_base"/>
    <child link="right_index_1"/>
    <axis xyz="0 0 -1"/>
    <limit effort="10" lower="0" upper="1.344277" velocity="2"/>
  </joint>
  <!-- ============================================================= -->
  <!-- INDEX RUBBER 1                                                -->
  <!-- ============================================================= -->
  <link name="right_index_rubber_1">
    <inertial>
      <origin rpy="0 0 0" xyz="4.12805956806483E-07 -0.000277556595871697 -0.00810725944560028"/>
      <mass value="0.00100751145071282"/>
      <inertia ixx="9.52705542669085E-08" ixy="-6.53021203153016E-13" ixz="2.06718585520476E-12" iyy="6.33360703776505E-08" iyz="-1.10143899913928E-08" izz="8.2378637909334E-08"/>
    </inertial>
    <!-- ================= VISUAL ================= -->
    <visual>
      <origin rpy="0 0 0" xyz="0 0 0"/>
      <geometry>
        <mesh filename="/workspace/external/rh56dfx_description/meshes/right/visual/right_index_rubber_1.STL"/>
      </geometry>
      <material name="">
        <color rgba="0.298039215686275 0.298039215686275 0.298039215686275 1"/>
      </material>
    </visual>
    <!-- ================= COLLISION ================= -->
    <collision>
      <origin rpy="0 0 0" xyz="0 0 0"/>
      <geometry>
        <mesh filename="/workspace/external/rh56dfx_description/meshes/right/collision/right_index_rubber_1.STL"/>
      </geometry>
      <material name="">
        <color rgba="1 0 0 1"/>
      </material>
    </collision>
  </link>
  <!-- ================= JOINT ================= -->
  <joint name="right_index_rubber_1_joint" type="fixed">
    <origin rpy="1.5043 1.5708 1.5708" xyz="0.010962 0.015475 0.0058991"/>
    <parent link="right_index_1"/>
    <child link="right_index_rubber_1"/>
  </joint>
  <!-- ============================================================= -->
  <!-- INDEX 2                                                       -->
  <!-- ============================================================= -->
  <link name="right_index_2">
    <inertial>
      <origin rpy="0 0 0" xyz="0.000846426534759137 0.0159697001083362 0.00510099034129251"/>
      <mass value="0.00329259625036443"/>
      <inertia ixx="8.02619712389298E-07" ixy="-2.71403950553563E-07" ixz="-3.30964974651296E-11" iyy="2.63871633501356E-07" iyz="-7.26892151274215E-11" izz="9.31350792104698E-07"/>
    </inertial>
    <!-- ================= VISUAL ================= -->
    <visual>
      <origin rpy="0 0 0" xyz="0 0 0"/>
      <geometry>
        <mesh filename="/workspace/external/rh56dfx_description/meshes/right/visual/right_index_2.STL"/>
      </geometry>
      <material name="">
        <color rgba="1 1 1 1"/>
      </material>
    </visual>
    <!-- ================= COLLISION ================= -->
    <collision>
      <origin rpy="0 0 0" xyz="0 0 0"/>
      <geometry>
        <mesh filename="/workspace/external/rh56dfx_description/meshes/right/collision/right_index_2.STL"/>
      </geometry>
      <material name="">
        <color rgba="1 0 0 1"/>
      </material>
    </collision>
  </link>
  <!-- ================= JOINT ================= -->
  <joint name="right_index_2_joint" type="revolute">
    <origin rpy="0 0 0" xyz="0.0071189 0.031334 0.0008"/>
    <parent link="right_index_1"/>
    <child link="right_index_2"/>
    <axis xyz="0 0 -1"/>
    <limit effort="10" lower="0" upper="1.59562" velocity="2"/>
    <!-- Mimic behaviour -->
    <mimic joint="right_index_1_joint" multiplier="1.1169" offset="-0.15"/>
  </joint>
  <!-- ============================================================= -->
  <!-- INDEX RUBBER 2                                                -->
  <!-- ============================================================= -->
  <link name="right_index_rubber_2">
    <inertial>
      <origin rpy="0 0 0" xyz="-3.58356273424953E-06 0.0158538079871463 -0.000683080888343193"/>
      <mass value="0.00119003328901229"/>
      <inertia ixx="1.35901045730651E-07" ixy="-8.22113597047336E-11" ixz="8.26751437859069E-12" iyy="2.32704344501304E-08" iyz="-1.5965157571134E-08" izz="1.37434601512647E-07"/>
    </inertial>
    <!-- ================= VISUAL ================= -->
    <visual>
      <origin rpy="0 0 0" xyz="0 0 0"/>
      <geometry>
        <mesh filename="/workspace/external/rh56dfx_description/meshes/right/visual/right_index_rubber_2.STL"/>
      </geometry>
      <material name="">
        <color rgba="0.298039215686275 0.298039215686275 0.298039215686275 1"/>
      </material>
    </visual>
    <!-- ================= COLLISION ================= -->
    <collision>
      <origin rpy="0 0 0" xyz="0 0 0"/>
      <geometry>
        <mesh filename="/workspace/external/rh56dfx_description/meshes/right/collision/right_index_rubber_2.STL"/>
      </geometry>
      <material name="">
        <color rgba="1 0 0 1"/>
      </material>
    </collision>
  </link>
  <!-- ================= JOINT ================= -->
  <joint name="right_index_rubber_2_joint" type="fixed">
    <origin rpy="1.6908 1.5638 1.5708" xyz="0.0070147 0.012486 0.0050557"/>
    <parent link="right_index_2"/>
    <child link="right_index_rubber_2"/>
  </joint>
  <!-- ============================================================= -->
  <!-- INDEX PAD                                                     -->
  <!-- ============================================================= -->
  <link name="right_index_pad">
    <inertial>
      <origin rpy="0 0 0" xyz="-4.72675732283989E-06 -0.00107358726165793 -0.000867322927155814"/>
      <mass value="4.91580635340277E-05"/>
      <inertia ixx="5.5578818727044E-11" ixy="-2.56095658110701E-14" ixz="3.01618774673413E-13" iyy="6.99839853074953E-11" iyz="-4.83794966411374E-12" izz="1.11177015808293E-10"/>
    </inertial>
    <!-- ================= VISUAL ================= -->
    <visual>
      <origin rpy="0 0 0" xyz="0 0 0"/>
      <geometry>
        <mesh filename="/workspace/external/rh56dfx_description/meshes/right/visual/right_index_pad.STL"/>
      </geometry>
      <material name="">
        <color rgba="0.298039215686275 0.298039215686275 0.298039215686275 1"/>
      </material>
    </visual>
    <!-- ================= COLLISION ================= -->
    <collision>
      <origin rpy="0 0 0" xyz="0 0 0"/>
      <geometry>
        <mesh filename="/workspace/external/rh56dfx_description/meshes/right/collision/right_index_pad.STL"/>
      </geometry>
      <material name="">
        <color rgba="1 0 0 1"/>
      </material>
    </collision>
  </link>
  <!-- ================= JOINT ================= -->
  <joint name="right_index_pad_joint" type="fixed">
    <origin rpy="0.0696904105640824 -4.36438134320539E-05 -0.000362025901862688" xyz="3.00243817556722E-05 0.0237882080122733 0.00562165601406409"/>
    <parent link="right_index_rubber_2"/>
    <child link="right_index_pad"/>
  </joint>
  <!-- ============================================================= -->
  <!-- INDEX TIP                                                     -->
  <!-- ============================================================= -->
  <link name="right_index_tip">
    <inertial>
      <origin rpy="0 0 0" xyz="-0.000856665440566062 1.72386023511439E-08 -0.00102183804462784"/>
      <mass value="4.8581150755806E-05"/>
      <inertia ixx="7.21518593802518E-11" ixy="-8.82984500824386E-16" ixz="-6.19021389144841E-12" iyy="4.34288558152482E-11" iyz="-6.09787415609971E-16" izz="9.51176981115546E-11"/>
    </inertial>
    <!-- ================= VISUAL ================= -->
    <visual>
      <origin rpy="0 0 0" xyz="0 0 0"/>
      <geometry>
        <mesh filename="/workspace/external/rh56dfx_description/meshes/right/visual/right_index_tip.STL"/>
      </geometry>
      <material name="">
        <color rgba="0.298039215686275 0.298039215686275 0.298039215686275 1"/>
      </material>
    </visual>
    <!-- ================= COLLISION ================= -->
    <collision>
      <origin rpy="0 0 0" xyz="0 0 0"/>
      <geometry>
        <mesh filename="/workspace/external/rh56dfx_description/meshes/right/collision/right_index_tip.STL"/>
      </geometry>
      <material name="">
        <color rgba="1 0 0 1"/>
      </material>
    </collision>
  </link>
  <!-- ================= JOINT ================= -->
  <joint name="right_index_tip_joint" type="fixed">
    <origin rpy="-0.0132578490113875 -1.15442763241846 -1.55866618437752" xyz="1.3021716642192E-05 0.0312210274719888 0.00245735122593096"/>
    <parent link="right_index_rubber_2"/>
    <child link="right_index_tip"/>
  </joint>
  <!-- ============================================================= -->
  <!-- MIDDLE 1                                                      -->
  <!-- ============================================================= -->
  <link name="right_middle_1">
    <inertial>
      <origin rpy="0 0 0" xyz="0.000461536885984493 0.0116516125222251 0.00589995181961714"/>
      <mass value="0.00313593954054027"/>
      <inertia ixx="1.40231746759186E-06" ixy="-1.11031857346658E-07" ixz="2.76776871415406E-13" iyy="4.3361687442049E-07" iyz="-2.06120095699905E-11" izz="1.46953912178466E-06"/>
    </inertial>
    <!-- ================= VISUAL ================= -->
    <visual>
      <origin rpy="0 0 0" xyz="0 0 0"/>
      <geometry>
        <mesh filename="/workspace/external/rh56dfx_description/meshes/right/visual/right_middle_1.STL"/>
      </geometry>
      <material name="">
        <color rgba="1 1 1 1"/>
      </material>
    </visual>
    <!-- ================= COLLISION ================= -->
    <collision>
      <origin rpy="0 0 0" xyz="0 0 0"/>
      <geometry>
        <mesh filename="/workspace/external/rh56dfx_description/meshes/right/collision/right_middle_1.STL"/>
      </geometry>
      <material name="">
        <color rgba="1 0 0 1"/>
      </material>
    </collision>
  </link>
  <!-- ================= JOINT ================= -->
  <joint name="right_middle_1_joint" type="revolute">
    <origin rpy="3.14159265358979 0 3.1415926535899" xyz="0.00224533001909609 0.104700000000653 0.0288000018363736"/>
    <parent link="right_hand_base"/>
    <child link="right_middle_1"/>
    <axis xyz="0 0 -1"/>
    <limit effort="10" lower="0" upper="1.344277" velocity="2"/>
  </joint>
  <!-- ============================================================= -->
  <!-- MIDDLE RUBBER 1                                               -->
  <!-- ============================================================= -->
  <link name="right_middle_rubber_1">
    <inertial>
      <origin rpy="0 0 0" xyz="5.03351059822493E-07 -0.000277151585263605 -0.00810672582334755"/>
      <mass value="0.00100745318455656"/>
      <inertia ixx="9.5260411594105E-08" ixy="-6.69431445254942E-14" ixz="2.63670575694768E-12" iyy="6.33300913372493E-08" iyz="-1.10094870847211E-08" izz="8.23746545988052E-08"/>
    </inertial>
    <!-- ================= VISUAL ================= -->
    <visual>
      <origin rpy="0 0 0" xyz="0 0 0"/>
      <geometry>
        <mesh filename="/workspace/external/rh56dfx_description/meshes/right/visual/right_middle_rubber_1.STL"/>
      </geometry>
      <material name="">
        <color rgba="0.298039215686275 0.298039215686275 0.298039215686275 1"/>
      </material>
    </visual>
    <!-- ================= COLLISION ================= -->
    <collision>
      <origin rpy="0 0 0" xyz="0 0 0"/>
      <geometry>
        <mesh filename="/workspace/external/rh56dfx_description/meshes/right/collision/right_middle_rubber_1.STL"/>
      </geometry>
      <material name="">
        <color rgba="1 0 0 1"/>
      </material>
    </collision>
  </link>
  <!-- ================= JOINT ================= -->
  <joint name="right_middle_rubber_1_joint" type="fixed">
    <origin rpy="1.5043 1.5708 1.5708" xyz="0.010962 0.015475 0.0059"/>
    <parent link="right_middle_1"/>
    <child link="right_middle_rubber_1"/>
  </joint>
  <!-- ============================================================= -->
  <!-- MIDDLE 2                                                      -->
  <!-- ============================================================= -->
  <link name="right_middle_2">
    <inertial>
      <origin rpy="0 0 0" xyz="0.00141024346448289 0.0172292690724932 0.00510100142947595"/>
      <mass value="0.0100500190545245"/>
      <inertia ixx="1.00699767773869E-06" ixy="-3.53466950101424E-07" ixz="-4.09738501779845E-11" iyy="3.12317850665907E-07" iyz="-8.97245492379795E-11" izz="1.17274745258556E-06"/>
    </inertial>
    <!-- ================= VISUAL ================= -->
    <visual>
      <origin rpy="0 0 0" xyz="0 0 0"/>
      <geometry>
        <mesh filename="/workspace/external/rh56dfx_description/meshes/right/visual/right_middle_2.STL"/>
      </geometry>
      <material name="">
        <color rgba="1 1 1 1"/>
      </material>
    </visual>
    <!-- ================= COLLISION ================= -->
    <collision>
      <origin rpy="0 0 0" xyz="0 0 0"/>
      <geometry>
        <mesh filename="/workspace/external/rh56dfx_description/meshes/right/collision/right_middle_2.STL"/>
      </geometry>
      <material name="">
        <color rgba="1 0 0 1"/>
      </material>
    </collision>
  </link>
  <!-- ================= JOINT ================= -->
  <joint name="right_middle_2_joint" type="revolute">
    <origin rpy="0 0 0" xyz="0.0071189 0.031334 0.0008"/>
    <parent link="right_middle_1"/>
    <child link="right_middle_2"/>
    <axis xyz="0 0 -1"/>
    <limit effort="10" lower="0" upper="1.59562" velocity="2"/>
    <mimic joint="right_middle_1_joint" multiplier="1.1169" offset="-0.15"/>
  </joint>
  <!-- ============================================================= -->
  <!-- MIDDLE RUBBER 2                                               -->
  <!-- ============================================================= -->
  <link name="right_middle_rubber_2">
    <inertial>
      <origin rpy="0 0 0" xyz="-7.78660795392946E-06 0.0179695960463814 -0.000804223911115579"/>
      <mass value="0.0013048811432833"/>
      <inertia ixx="1.76860633231279E-07" ixy="-1.72710567602084E-10" ixz="1.86622775329523E-11" iyy="2.52989855308437E-08" iyz="-1.81372167935848E-08" izz="1.78751424236927E-07"/>
    </inertial>
    <!-- ================= VISUAL ================= -->
    <visual>
      <origin rpy="0 0 0" xyz="0 0 0"/>
      <geometry>
        <mesh filename="/workspace/external/rh56dfx_description/meshes/right/visual/right_middle_rubber_2.STL"/>
      </geometry>
      <material name="">
        <color rgba="0.298039215686275 0.298039215686275 0.298039215686275 1"/>
      </material>
    </visual>
    <!-- ================= COLLISION ================= -->
    <collision>
      <origin rpy="0 0 0" xyz="0 0 0"/>
      <geometry>
        <mesh filename="/workspace/external/rh56dfx_description/meshes/right/collision/right_middle_rubber_2.STL"/>
      </geometry>
      <material name="">
        <color rgba="1 0 0 1"/>
      </material>
    </collision>
  </link>
  <!-- ================= JOINT ================= -->
  <joint name="right_middle_rubber_2_joint" type="fixed">
    <origin rpy="1.7195 1.5657 1.5708" xyz="0.0072845 0.012518 0.0050018"/>
    <parent link="right_middle_2"/>
    <child link="right_middle_rubber_2"/>
  </joint>
  <!-- ============================================================= -->
  <!-- MIDDLE PAD                                                    -->
  <!-- ============================================================= -->
  <link name="right_middle_pad">
    <inertial>
      <origin rpy="0 0 0" xyz="-9.14565195887437E-06 -0.000840646466128969 -0.000949483924762157"/>
      <mass value="5.07972430810532E-05"/>
      <inertia ixx="4.94396351444529E-11" ixy="-7.91548004686604E-15" ixz="5.40378231833977E-13" iyy="7.44594898392844E-11" iyz="-8.17507834331293E-13" izz="1.05507123106656E-10"/>
    </inertial>
    <!-- ================= VISUAL ================= -->
    <visual>
      <origin rpy="0 0 0" xyz="0 0 0"/>
      <geometry>
        <mesh filename="/workspace/external/rh56dfx_description/meshes/right/visual/right_middle_pad.STL"/>
      </geometry>
      <material name="">
        <color rgba="0.298039215686275 0.298039215686275 0.298039215686275 1"/>
      </material>
    </visual>
    <!-- ================= COLLISION ================= -->
    <collision>
      <origin rpy="0 0 0" xyz="0 0 0"/>
      <geometry>
        <mesh filename="/workspace/external/rh56dfx_description/meshes/right/collision/right_middle_pad.STL"/>
      </geometry>
      <material name="">
        <color rgba="1 0 0 1"/>
      </material>
    </collision>
  </link>
  <!-- ================= JOINT ================= -->
  <joint name="right_middle_pad_joint" type="fixed">
    <origin rpy="-0.00517966246514453 0 5.23567777294042E-05" xyz="5.25438080711468E-05 0.0275018148385101 0.00545981715229053"/>
    <parent link="right_middle_rubber_2"/>
    <child link="right_middle_pad"/>
  </joint>
  <!-- ============================================================= -->
  <!-- MIDDLE TIP                                                    -->
  <!-- ============================================================= -->
  <link name="right_middle_tip">
    <inertial>
      <origin rpy="0 0 0" xyz="-0.000704283128653865 1.67839236536738E-08 -0.00102507470098162"/>
      <mass value="4.91005965538781E-05"/>
      <inertia ixx="7.4817666907452E-11" ixy="-2.50173118998556E-16" ixz="-8.35780307730688E-12" iyy="4.40425756472355E-11" iyz="-5.5138528291299E-16" izz="9.36024416007487E-11"/>
    </inertial>
    <!-- ================= VISUAL ================= -->
    <visual>
      <origin rpy="0 0 0" xyz="0 0 0"/>
      <geometry>
        <mesh filename="/workspace/external/rh56dfx_description/meshes/right/visual/right_middle_tip.STL"/>
      </geometry>
      <material name="">
        <color rgba="0.298039215686275 0.298039215686275 0.298039215686275 1"/>
      </material>
    </visual>
    <!-- ================= COLLISION ================= -->
    <collision>
      <origin rpy="0 0 0" xyz="0 0 0"/>
      <geometry>
        <mesh filename="/workspace/external/rh56dfx_description/meshes/right/collision/right_middle_tip.STL"/>
      </geometry>
      <material name="">
        <color rgba="1 0 0 1"/>
      </material>
    </collision>
  </link>
  <!-- ================= JOINT ================= -->
  <joint name="right_middle_tip_joint" type="fixed">
    <origin rpy="-0.0212852224193426 -1.10096720678329 -1.55181437467009" xyz="2.14438757245201E-05 0.0347938058137771 0.00223431434988275"/>
    <parent link="right_middle_rubber_2"/>
    <child link="right_middle_tip"/>
  </joint>
  <!-- ============================================================= -->
  <!-- RING 1                                                        -->
  <!-- ============================================================= -->
  <link name="right_ring_1">
    <inertial>
      <origin rpy="0 0 0" xyz="0.000461529808951755 0.0116516281013052 0.00589997080611728"/>
      <mass value="0.00881199089266141"/>
      <inertia ixx="1.40231626030129E-06" ixy="-1.11031417680307E-07" ixz="-4.11132319980449E-13" iyy="4.33615995682151E-07" iyz="-1.87827283697014E-11" izz="1.46953842944211E-06"/>
    </inertial>
    <!-- ================= VISUAL ================= -->
    <visual>
      <origin rpy="0 0 0" xyz="0 0 0"/>
      <geometry>
        <mesh filename="/workspace/external/rh56dfx_description/meshes/right/visual/right_ring_1.STL"/>
      </geometry>
      <material name="">
        <color rgba="1 1 1 1"/>
      </material>
    </visual>
    <!-- ================= COLLISION ================= -->
    <collision>
      <origin rpy="0 0 0" xyz="0 0 0"/>
      <geometry>
        <mesh filename="/workspace/external/rh56dfx_description/meshes/right/collision/right_ring_1.STL"/>
      </geometry>
      <material name="">
        <color rgba="1 0 0 1"/>
      </material>
    </collision>
  </link>
  <!-- ================= JOINT ================= -->
  <joint name="right_ring_1_joint" type="revolute">
    <origin rpy="-3.10687289847015 0 -3.14159265358979" xyz="0.0022453318336232 0.104505254785017 0.00956298212738258"/>
    <parent link="right_hand_base"/>
    <child link="right_ring_1"/>
    <axis xyz="0 0 -1"/>
    <limit effort="10" lower="0" upper="1.344277" velocity="2"/>
  </joint>
  <!-- ============================================================= -->
  <!-- RING RUBBER 1                                                 -->
  <!-- ============================================================= -->
  <link name="right_ring_rubber_1">
    <inertial>
      <origin rpy="0 0 0" xyz="5.21559770035084E-07 -0.00027711873325572 -0.00810658713183561"/>
      <mass value="0.00100744692221204"/>
      <inertia ixx="9.52590748325436E-08" ixy="3.14419307320589E-13" ixz="2.58919901199866E-12" iyy="6.33292870038947E-08" iyz="-1.10085765951351E-08" izz="8.23741747990365E-08"/>
    </inertial>
    <!-- ================= VISUAL ================= -->
    <visual>
      <origin rpy="0 0 0" xyz="0 0 0"/>
      <geometry>
        <mesh filename="/workspace/external/rh56dfx_description/meshes/right/visual/right_ring_rubber_1.STL"/>
      </geometry>
      <material name="">
        <color rgba="0.298039215686275 0.298039215686275 0.298039215686275 1"/>
      </material>
    </visual>
    <!-- ================= COLLISION ================= -->
    <collision>
      <origin rpy="0 0 0" xyz="0 0 0"/>
      <geometry>
        <mesh filename="/workspace/external/rh56dfx_description/meshes/right/collision/right_ring_rubber_1.STL"/>
      </geometry>
      <material name="">
        <color rgba="1 0 0 1"/>
      </material>
    </collision>
  </link>
  <!-- ================= JOINT ================= -->
  <joint name="right_ring_rubber_1_joint" type="fixed">
    <origin rpy="1.5043 1.5708 1.5708" xyz="0.010962 0.015475 0.0059"/>
    <parent link="right_ring_1"/>
    <child link="right_ring_rubber_1"/>
  </joint>
  <!-- ============================================================= -->
  <!-- RING 2                                                        -->
  <!-- ============================================================= -->
  <link name="right_ring_2">
    <inertial>
      <origin rpy="0 0 0" xyz="0.000846433960369861 0.0159697337276641 0.00510097835693506"/>
      <mass value="0.00925228640460226"/>
      <inertia ixx="8.02618879630184E-07" ixy="-2.71404191071111E-07" ixz="-3.36930516321696E-11" iyy="2.63871764022255E-07" iyz="-7.22696351064651E-11" izz="9.31349226423688E-07"/>
    </inertial>
    <!-- ================= VISUAL ================= -->
    <visual>
      <origin rpy="0 0 0" xyz="0 0 0"/>
      <geometry>
        <mesh filename="/workspace/external/rh56dfx_description/meshes/right/visual/right_ring_2.STL"/>
      </geometry>
      <material name="">
        <color rgba="1 1 1 1"/>
      </material>
    </visual>
    <!-- ================= COLLISION ================= -->
    <collision>
      <origin rpy="0 0 0" xyz="0 0 0"/>
      <geometry>
        <mesh filename="/workspace/external/rh56dfx_description/meshes/right/collision/right_ring_2.STL"/>
      </geometry>
      <material name="">
        <color rgba="1 0 0 1"/>
      </material>
    </collision>
  </link>
  <!-- ================= JOINT ================= -->
  <joint name="right_ring_2_joint" type="revolute">
    <origin rpy="0 0 0" xyz="0.0071189 0.031334 0.0008"/>
    <parent link="right_ring_1"/>
    <child link="right_ring_2"/>
    <axis xyz="0 0 -1"/>
    <limit effort="10" lower="0" upper="1.59562" velocity="2"/>
    <mimic joint="right_ring_1_joint" multiplier="1.1169" offset="-0.15"/>
  </joint>
  <!-- ============================================================= -->
  <!-- RING RUBBER 2                                                 -->
  <!-- ============================================================= -->
  <link name="right_ring_rubber_2">
    <inertial>
      <origin rpy="0 0 0" xyz="3.86139388208794E-06 0.0158537656121268 -0.000683069774846418"/>
      <mass value="0.00119005024637797"/>
      <inertia ixx="1.3590239064115E-07" ixy="9.33554288461355E-11" ixz="-8.65081377481482E-12" iyy="2.32706293689469E-08" iyz="-1.59652938631654E-08" izz="1.37436006921243E-07"/>
    </inertial>
    <!-- ================= VISUAL ================= -->
    <visual>
      <origin rpy="0 0 0" xyz="0 0 0"/>
      <geometry>
        <mesh filename="/workspace/external/rh56dfx_description/meshes/right/visual/right_ring_rubber_2.STL"/>
      </geometry>
      <material name="">
        <color rgba="0.298039215686275 0.298039215686275 0.298039215686275 1"/>
      </material>
    </visual>
    <!-- ================= COLLISION ================= -->
    <collision>
      <origin rpy="0 0 0" xyz="0 0 0"/>
      <geometry>
        <mesh filename="/workspace/external/rh56dfx_description/meshes/right/collision/right_ring_rubber_2.STL"/>
      </geometry>
      <material name="">
        <color rgba="1 0 0 1"/>
      </material>
    </collision>
  </link>
  <!-- ================= JOINT ================= -->
  <joint name="right_ring_rubber_2_joint" type="fixed">
    <origin rpy="1.69435491572921 1.55693797492977 1.5707963267949" xyz="0.00685339412965266 0.0123693480371164 0.0050852021440689"/>
    <parent link="right_ring_2"/>
    <child link="right_ring_rubber_2"/>
  </joint>
  <!-- ============================================================= -->
  <!-- RING PAD                                                      -->
  <!-- ============================================================= -->
  <link name="right_ring_pad">
    <inertial>
      <origin rpy="0 0 0" xyz="4.93671885636732E-06 -0.00107358739426554 -0.000867321750761263"/>
      <mass value="4.91580616058684E-05"/>
      <inertia ixx="5.55789971203642E-11" ixy="2.82945412870402E-14" ixz="-3.17865063864845E-13" iyy="6.99839909074725E-11" iyz="-4.83793120453107E-12" izz="1.11176836090907E-10"/>
    </inertial>
    <!-- ================= VISUAL ================= -->
    <visual>
      <origin rpy="0 0 0" xyz="0 0 0"/>
      <geometry>
        <mesh filename="/workspace/external/rh56dfx_description/meshes/right/visual/right_ring_pad.STL"/>
      </geometry>
      <material name="">
        <color rgba="0.298039215686275 0.298039215686275 0.298039215686275 1"/>
      </material>
    </visual>
    <!-- ================= COLLISION ================= -->
    <collision>
      <origin rpy="0 0 0" xyz="0 0 0"/>
      <geometry>
        <mesh filename="/workspace/external/rh56dfx_description/meshes/right/collision/right_ring_pad.STL"/>
      </geometry>
      <material name="">
        <color rgba="1 0 0 1"/>
      </material>
    </collision>
  </link>
  <!-- ================= JOINT ================= -->
  <joint name="right_ring_pad_joint" type="fixed">
    <origin rpy="0.069690128142456 5.13938714334209E-05 0.000413828517329857" xyz="-3.19252405448149E-05 0.023788208012268 0.0056216455404758"/>
    <parent link="right_ring_rubber_2"/>
    <child link="right_ring_pad"/>
  </joint>
  <!-- ============================================================= -->
  <!-- RING TIP                                                      -->
  <!-- ============================================================= -->
  <link name="right_ring_tip">
    <inertial>
      <origin rpy="0 0 0" xyz="-0.000856664915059729 1.84558855672104E-08 -0.00102183703604269"/>
      <mass value="4.85811800950388E-05"/>
      <inertia ixx="7.21518845124189E-11" ixy="-9.06674000673522E-16" ixz="-6.19024133610583E-12" iyy="4.3428909706311E-11" iyz="-6.22904562534474E-16" izz="9.5117698350311E-11"/>
    </inertial>
    <!-- ================= VISUAL ================= -->
    <visual>
      <origin rpy="0 0 0" xyz="0 0 0"/>
      <geometry>
        <mesh filename="/workspace/external/rh56dfx_description/meshes/right/visual/right_ring_tip.STL"/>
      </geometry>
      <material name="">
        <color rgba="0.298039215686275 0.298039215686275 0.298039215686275 1"/>
      </material>
    </visual>
    <!-- ================= COLLISION ================= -->
    <collision>
      <origin rpy="0 0 0" xyz="0 0 0"/>
      <geometry>
        <mesh filename="/workspace/external/rh56dfx_description/meshes/right/collision/right_ring_tip.STL"/>
      </geometry>
      <material name="">
        <color rgba="1 0 0 1"/>
      </material>
    </collision>
  </link>
  <!-- ================= JOINT ================= -->
  <joint name="right_ring_tip_joint" type="fixed">
    <origin rpy="0.0139894535346192 -1.15442399923571 -1.58358580818303" xyz="-1.40578386722194E-05 0.031221027471983 0.00245734551696726"/>
    <parent link="right_ring_rubber_2"/>
    <child link="right_ring_tip"/>
  </joint>
  <!-- ============================================================= -->
  <!-- LITTLE 1                                                      -->
  <!-- ============================================================= -->
  <link name="right_little_1">
    <inertial>
      <origin rpy="0 0 0" xyz="0.000461535865007925 0.0116516313664518 0.00589997438900475"/>
      <mass value="0.00881199742105397"/>
      <inertia ixx="1.4023164476314E-06" ixy="-1.11031114078783E-07" ixz="-6.64626469397567E-13" iyy="4.33616376571531E-07" iyz="-1.83961469266843E-11" izz="1.46953909500208E-06"/>
    </inertial>
    <!-- ================= VISUAL ================= -->
    <visual>
      <origin rpy="0 0 0" xyz="0 0 0"/>
      <geometry>
        <mesh filename="/workspace/external/rh56dfx_description/meshes/right/visual/right_little_1.STL"/>
      </geometry>
      <material name="">
        <color rgba="1 1 1 1"/>
      </material>
    </visual>
    <!-- ================= COLLISION ================= -->
    <collision>
      <origin rpy="0 0 0" xyz="0 0 0"/>
      <geometry>
        <mesh filename="/workspace/external/rh56dfx_description/meshes/right/collision/right_little_1.STL"/>
      </geometry>
      <material name="">
        <color rgba="1 0 0 1"/>
      </material>
    </collision>
  </link>
  <!-- ================= JOINT ================= -->
  <joint name="right_little_1_joint" type="revolute">
    <origin rpy="-3.0387289847015 0 -3.14159265358979" xyz="0.00224533363585604 0.103303988640658 -0.00963748173991816"/>
    <parent link="right_hand_base"/>
    <child link="right_little_1"/>
    <axis xyz="0 0 -1"/>
    <limit effort="10" lower="0" upper="1.344277" velocity="2"/>
  </joint>
  <!-- ============================================================= -->
  <!-- LITTLE RUBBER 1                                               -->
  <!-- ============================================================= -->
  <link name="right_little_rubber_1">
    <inertial>
      <origin rpy="0 0 0" xyz="5.20179807662197E-07 -0.000277124687351721 -0.00810660245069689"/>
      <mass value="0.00100745340016915"/>
      <inertia ixx="9.5259604318723E-08" ixy="2.51290768845785E-13" ixz="2.57994342884682E-12" iyy="6.33296342901818E-08" iyz="-1.10088384074955E-08" izz="8.23744454855254E-08"/>
    </inertial>
    <!-- ================= VISUAL ================= -->
    <visual>
      <origin rpy="0 0 0" xyz="0 0 0"/>
      <geometry>
        <mesh filename="/workspace/external/rh56dfx_description/meshes/right/visual/right_little_rubber_1.STL"/>
      </geometry>
      <material name="">
        <color rgba="0.298039215686275 0.298039215686275 0.298039215686275 1"/>
      </material>
    </visual>
    <!-- ================= COLLISION ================= -->
    <collision>
      <origin rpy="0 0 0" xyz="0 0 0"/>
      <geometry>
        <mesh filename="/workspace/external/rh56dfx_description/meshes/right/collision/right_little_rubber_1.STL"/>
      </geometry>
      <material name="">
        <color rgba="1 0 0 1"/>
      </material>
    </collision>
  </link>
  <!-- ================= JOINT ================= -->
  <joint name="right_little_rubber_1_joint" type="fixed">
    <origin rpy="1.5043 1.5708 1.5708" xyz="0.010962 0.015475 0.0059"/>
    <parent link="right_little_1"/>
    <child link="right_little_rubber_1"/>
  </joint>
  <!-- ============================================================= -->
  <!-- LITTLE 2                                                      -->
  <!-- ============================================================= -->
  <link name="right_little_2">
    <inertial>
      <origin rpy="0 0 0" xyz="-9.65934753168612E-05 0.0131706385669229 0.00510089546104599"/>
      <mass value="0.00735975645438558"/>
      <inertia ixx="4.52987650882817E-07" ixy="-1.39947116144588E-07" ixz="-1.99302269280599E-11" iyy="1.74903368778748E-07" iyz="-4.32909879787788E-11" izz="5.20977818958806E-07"/>
    </inertial>
    <!-- ================= VISUAL ================= -->
    <visual>
      <origin rpy="0 0 0" xyz="0 0 0"/>
      <geometry>
        <mesh filename="/workspace/external/rh56dfx_description/meshes/right/visual/right_little_2.STL"/>
      </geometry>
      <material name="">
        <color rgba="1 1 1 1"/>
      </material>
    </visual>
    <!-- ================= COLLISION ================= -->
    <collision>
      <origin rpy="0 0 0" xyz="0 0 0"/>
      <geometry>
        <mesh filename="/workspace/external/rh56dfx_description/meshes/right/collision/right_little_2.STL"/>
      </geometry>
      <material name="">
        <color rgba="1 0 0 1"/>
      </material>
    </collision>
  </link>
  <!-- ================= JOINT ================= -->
  <joint name="right_little_2_joint" type="revolute">
    <origin rpy="0 0 0" xyz="0.0071189 0.031334 0.0109999999999999995"/>
    <parent link="right_little_1"/>
    <child link="right_little_2"/>
    <axis xyz="0 0 -1"/>
    <limit effort="10" lower="0" upper="1.59562" velocity="2"/>
    <mimic joint="right_little_1_joint" multiplier="1.1169" offset="-0.15"/>
  </joint>
  <!-- ============================================================= -->
  <!-- LITTLE RUBBER 2                                               -->
  <!-- ============================================================= -->
  <link name="right_little_rubber_2">
    <inertial>
      <origin rpy="0 0 0" xyz="1.62425876137906E-07 0.0112748945844156 -0.000128890409676133"/>
      <mass value="0.000944695125035103"/>
      <inertia ixx="7.2727499654919E-08" ixy="5.77567509581988E-13" ixz="3.35299338499586E-13" iyy="1.97518492029983E-08" iyz="-1.31116172495388E-08" izz="7.2809424232253E-08"/>
    </inertial>
    <!-- ================= VISUAL ================= -->
    <visual>
      <origin rpy="0 0 0" xyz="0 0 0"/>
      <geometry>
        <mesh filename="/workspace/external/rh56dfx_description/meshes/right/visual/right_little_rubber_2.STL"/>
      </geometry>
      <material name="">
        <color rgba="0.298039215686275 0.298039215686275 0.298039215686275 1"/>
      </material>
    </visual>
    <!-- ================= COLLISION ================= -->
    <collision>
      <origin rpy="0 0 0" xyz="0 0 0"/>
      <geometry>
        <mesh filename="/workspace/external/rh56dfx_description/meshes/right/collision/right_little_rubber_2.STL"/>
      </geometry>
      <material name="">
        <color rgba="1 0 0 1"/>
      </material>
    </collision>
  </link>
  <!-- ================= JOINT ================= -->
  <joint name="right_little_rubber_2_joint" type="fixed">
    <origin rpy="-1.5639 1.5708 -1.5708" xyz="0.0060598 0.012028 -0.00510001089644316"/>
    <parent link="right_little_2"/>
    <child link="right_little_rubber_2"/>
  </joint>
  <!-- ============================================================= -->
  <!-- LITTLE PAD                                                    -->
  <!-- ============================================================= -->
  <link name="right_little_pad">
    <inertial>
      <origin rpy="0 0 0" xyz="1.18945155044847E-08 -0.000945393602624786 -0.000793542159615274"/>
      <mass value="4.11773981011346E-05"/>
      <inertia ixx="3.93905948672135E-11" ixy="-7.32805647857825E-16" ixz="1.2637926765438E-16" iyy="5.76290636184782E-11" iyz="-3.06558460120779E-12" izz="8.71440947947964E-11"/>
    </inertial>
    <!-- ================= VISUAL ================= -->
    <visual>
      <origin rpy="0 0 0" xyz="0 0 0"/>
      <geometry>
        <mesh filename="/workspace/external/rh56dfx_description/meshes/right/visual/right_little_pad.STL"/>
      </geometry>
      <material name="">
        <color rgba="0.298039215686275 0.298039215686275 0.298039215686275 1"/>
      </material>
    </visual>
    <!-- ================= COLLISION ================= -->
    <collision>
      <origin rpy="0 0 0" xyz="0 0 0"/>
      <geometry>
        <mesh filename="/workspace/external/rh56dfx_description/meshes/right/collision/right_little_pad.STL"/>
      </geometry>
      <material name="">
        <color rgba="1 0 0 1"/>
      </material>
    </collision>
  </link>
  <!-- ================= JOINT ================= -->
  <joint name="right_little_pad_joint" type="fixed">
    <origin rpy="0.234319161981939 0 0" xyz="0 0.0158106591438756 0.00622450938719539"/>
    <parent link="right_little_rubber_2"/>
    <child link="right_little_pad"/>
  </joint>
  <!-- ============================================================= -->
  <!-- LITTLE TIP                                                    -->
  <!-- ============================================================= -->
  <link name="right_little_tip">
    <inertial>
      <origin rpy="0 0 0" xyz="-0.000679510924646992 -6.02486744175068E-09 -0.000989969384403724"/>
      <mass value="5.12498578797036E-05"/>
      <inertia ixx="7.82782292969908E-11" ixy="-1.7772592370017E-16" ixz="-6.68409720589241E-12" iyy="4.68632553260876E-11" iyz="4.12841427346065E-17" izz="1.00471412022202E-10"/>
    </inertial>
    <!-- ================= VISUAL ================= -->
    <visual>
      <origin rpy="0 0 0" xyz="0 0 0"/>
      <geometry>
        <mesh filename="/workspace/external/rh56dfx_description/meshes/right/visual/right_little_tip.STL"/>
      </geometry>
      <material name="">
        <color rgba="0.298039215686275 0.298039215686275 0.298039215686275 1"/>
      </material>
    </visual>
    <!-- ================= COLLISION ================= -->
    <collision>
      <origin rpy="0 0 0" xyz="0 0 0"/>
      <geometry>
        <mesh filename="/workspace/external/rh56dfx_description/meshes/right/collision/right_little_tip.STL"/>
      </geometry>
      <material name="">
        <color rgba="1 0 0 1"/>
      </material>
    </collision>
  </link>
  <!-- ================= JOINT ================= -->
  <joint name="right_little_tip_joint" type="fixed">
    <origin rpy="0.00195594039193604 -1.19148502417136 -1.57079698453249" xyz="0 0.0235281291193636 0.00364793083244132"/>
    <parent link="right_little_rubber_2"/>
    <child link="right_little_tip"/>
  </joint>
  <!-- ============================================================= -->
  <!-- PALM                                                          -->
  <!-- ============================================================= -->
  <link name="right_palm">
    <inertial>
      <origin rpy="0 0 0" xyz="-0.00487476115291697 -0.00792590594988131 0.000407287403626957"/>
      <mass value="0.0103872606312152"/>
      <inertia ixx="4.32573922871556E-06" ixy="-1.82977028647607E-06" ixz="1.24432802967265E-07" iyy="5.02164658586136E-06" iyz="6.08810899531559E-07" izz="9.01614152193276E-06"/>
    </inertial>
    <!-- ================= VISUAL ================= -->
    <visual>
      <origin rpy="0 0 0" xyz="0 0 0"/>
      <geometry>
        <mesh filename="/workspace/external/rh56dfx_description/meshes/right/visual/right_palm.STL"/>
      </geometry>
      <material name="">
        <color rgba="0.298039215686275 0.298039215686275 0.298039215686275 1"/>
      </material>
    </visual>
    <!-- ================= COLLISION ================= -->
    <collision>
      <origin rpy="0 0 0" xyz="0 0 0"/>
      <geometry>
        <mesh filename="/workspace/external/rh56dfx_description/meshes/right/collision/right_palm.STL"/>
      </geometry>
      <material name="">
        <color rgba="1 0 0 1"/>
      </material>
    </collision>
  </link>
  <!-- ================= JOINT ================= -->
  <joint name="right_palm_joint" type="fixed">
    <origin rpy="-3.14159265242298 -1.57079623022433 3.14159265242298" xyz="-0.0127026878056337 0.0690814278199097 0.0114914368261144"/>
    <parent link="right_hand_base"/>
    <child link="right_palm"/>
  </joint>
</robot>
